Workbook

Sheet Films
A1: ID | B1: Titre français | C1: Titre original | D1: Année | E1: Type | F1: Durée (min) | G1: Pays | H1: Réalisation | I1: Scénario | J1: Image | K1: Montage | L1: Décors | M1: Musique | N1: Production | O1: Distribution artistique | P1: Équipe technique | Q1: Synopsis | R1: Extraits | S1: Analyse | T1: Bibliographie | U1: Affiche | V1: Légende affiche | W1: Source affiche | X1: Liens chronologie | Y1: Mots-clés | Z1: Sources | AA1: Statut | AB1: ID normalisé V22 | AC1: IDs entourage — distribution artistique | AD1: IDs entourage — équipe technique
A2: rwf-1966-this-night | B2: This night | C2: This night | D2: 1966 | E2: Court-métrage | G2: RFA | H2: Rainer Werner Fassbinder
A3: rwf-1966-le-clochard | B3: Le Clochard | C3: Der Stadtstreicher | D3: 1966 | E3: Court-métrage | F3: 10 | G3: RFA | H3: Rainer Werner Fassbinder | I3: Rainer Werner Fassbinder | J3: Michael Fengler ; Josef Jung | N3: Roser Film | O3: Christoph Roser : le clochard Susanne Schimkus : la serveuse Michael Fengler : un homme Thomas Fengler : un homme Irm Hermann : Frau Pigue | P3: Format : noir et blanc, mono Genre : court métrage dramatique Sortie : 1966 | Q3: Un clochard trouve un pistolet dans la rue. | Z3: Wikipédia : https://fr.wikipedia.org/wiki/Le_Clochard | AB3: film-1966-le-clochard
A4: rwf-1967-petit-chaos | B4: Petit chaos | C4: Das kleine Chaos | D4: 1967 | E4: Court-métrage | F4: 9 | G4: RFA | H4: Rainer Werner Fassbinder | I4: Rainer Werner Fassbinder | J4: Michael Fengler | N4: Roser Film | O4: Christoph Roser : Theo Marite Greiselis : Marite Rainer Werner Fassbinder : Franz Lilo Pempeit : Mme Eder | P4: Format : noir et blanc, 1,37:1, mono Genre : court métrage de comédie Sortie : 1967 | Q4: Theo, Marite et Franz tentent de gagner de l’argent en vendant des revues en porte-à-porte. Après leurs échecs répétés, ils décident de commettre de petits vols. | Z4: Wikipédia : https://fr.wikipedia.org/wiki/Le_Petit_Chaos | AB4: film-1967-petit-chaos
A5: rwf-1969-amour-plus-froid | B5: L’Amour est plus froid que la mort | C5: Liebe ist kälter als der Tod | D5: 1969 | E5: Long métrage | F5: 88 | G5: RFA | H5: Rainer Werner Fassbinder | I5: Rainer Werner Fassbinder | K5: Franz Walsch (pseudonyme de Rainer Werner Fassbinder) | L5: Ulli Lommel ; Rainer Werner Fassbinder | M5: Peer Raben ; Holga Münzer | N5: Antiteater-X-Film | O5: Rainer Werner Fassbinder : Franz Ulli Lommel : Bruno Hanna Schygulla : Joanna Hans Hirschmüller : Peter Katrin Schaake : la jeune femme dans le train Peter Berling : le cordonnier Irm Hermann : la vendeuse de lunettes Hannes Gromball : le client de Joanna Gisela Otto : une prostituée Ingrid Caven : une prostituée Ursula Strätz : une prostituée Les Olvides : Georges Peer Raben : Jürgen Peter Moland : un homme du syndicat Anastassios Karalas : le Turc Kurt Raab : le surveillant du supermarché Rudolf Waldemar Brem : le motard policier Yaak Karsunke : le commissaire Monoka Stadler : la jeune fille | P5: Son : Gottfried Hüngsberg Format : noir et blanc, 35 mm Tournage : 24 jours en avril 1969, Munich et environs Sortie RFA : 26 juin 1969 (Berlinale), puis 16 janvier 1970 | Q5: Franz, souteneur de petite envergure, refuse de s’allier à un syndicat du crime. Celui-ci lui envoie Bruno, qui forme avec Franz et sa compagne Joanna un trio de jeunes criminels. Bruno commet des crimes que la police impute à Franz, puis les deux hommes décident d’attaquer une banque. | U5: Films_images/L_Amour_est_plus_froid_que_la_mort.jpg | X5: 1969 | Z5: Wikipédia : https://fr.wikipedia.org/wiki/L%27amour_est_plus_froid_que_la_mort | AA5: À compléter | AB5: film-1969-l-amour-est-plus-froid-que-la-mort | AC5: =IF(O5="","",_xlfn.TEXTJOIN("; ",TRUE,IF(ISNUMBER(SEARCH('Référentiel entourage'!$B$2,O5)),'Référentiel entourage'!$A$2,""),IF(ISNUMBER(SEARCH('Référentiel entourage'!$B$3,O5)),'Référentiel entourage'!$A$3,""),IF(ISNUMBER(SEARCH('Référentiel entourage'!$B$4,O5)),'Référentiel entourage'!$A$4,""),IF(ISNUMBER(SEARCH('Référentiel entourage'!$B$5,O5)),'Référentiel entourage'!$A$5,""),IF(ISNUMBER(SEARCH('Référentiel entourage'!$B$6,O5)),'Référentiel entourage'!$A$6,""),IF(ISNUMBER(SEARCH('Référentiel entourage'!$B$7,O5)),'Référentiel entourage'!$A$7,""),IF(ISNUMBER(SEARCH('Référentiel entourage'!$B$8,O5)),'Référentiel entourage'!$A$8,""),IF(ISNUMBER(SEARCH('Référentiel entourage'!$B$9,O5)),'Référentiel entourage'!$A$9,""),IF(ISNUMBER(SEARCH('Référentiel entourage'!$B$10,O5)),'Référentiel entourage'!$A$10,""),IF(ISNUMBER(SEARCH('Référentiel entourage'!$B$11,O5)),'Référentiel entourage'!$A$11,""),IF(ISNUMBER(SEARCH('Référentiel entourage'!$B$12,O5)),'Référentiel entourage'!$A$12,""),IF(ISNUMBER(SEARCH('Référentiel entourage'!$B$13,O5)),'Référentiel entourage'!$A$13,""),IF(ISNUMBER(SEARCH('Référentiel entourage'!$B$14,O5)),'Référentiel entourage'!$A$14,""),IF(ISNUMBER(SEARCH('Référentiel entourage'!$B$15,O5)),'Référentiel entourage'!$A$15,""),IF(ISNUMBER(SEARCH('Référentiel entourage'!$B$16,O5)),'Référentiel entourage'!$A$16,""),IF(ISNUMBER(SEARCH('Référentiel entourage'!$B$17,O5)),'Référentiel entourage'!$A$17,""),IF(ISNUMBER(SEARCH('Référentiel entourage'!$B$18,O5)),'Référentiel entourage'!$A$18,""),IF(ISNUMBER(SEARCH('Référentiel entourage'!$B$19,O5)),'Référentiel entourage'!$A$19,""),IF(ISNUMBER(SEARCH('Référentiel entourage'!$B$20,O5)),'Référentiel entourage'!$A$20,""),IF(ISNUMBER(SEARCH('Référentiel entourage'!$B$21,O5)),'Référentiel entourage'!$A$21,""),IF(ISNUMBER(SEARCH('Référentiel entourage'!$B$22,O5)),'Référentiel entourage'!$A$22,""),IF(ISNUMBER(SEARCH('Référentiel entourage'!$B$23,O5)),'Référentiel entourage'!$A$23,""),IF(ISNUMBER(SEARCH('Référentiel entourage'!$B$24,O5)),'Référentiel entourage'!$A$24,""))) -> pers-ingrid-caven; pers-irm-hermann; pers-ulli-lommel; pers-kurt-raab; pers-peer-raben; pers-hanna-schygulla; pers-ursula-stratz | AD5: =_xlfn.LET(_xlpm.texte,_xlfn.TEXTJOIN(" | ",TRUE,H5:N5,P5),IF(_xlpm.texte="","",_xlfn.TEXTJOIN("; ",TRUE,IF(ISNUMBER(SEARCH('Référentiel entourage'!$B$2,_xlpm.texte)),'Référentiel entourage'!$A$2,""),IF(ISNUMBER(SEARCH('Référentiel entourage'!$B$3,_xlpm.texte)),'Référentiel entourage'!$A$3,""),IF(ISNUMBER(SEARCH('Référentiel entourage'!$B$4,_xlpm.texte)),'Référentiel entourage'!$A$4,""),IF(ISNUMBER(SEARCH('Référentiel entourage'!$B$5,_xlpm.texte)),'Référentiel entourage'!$A$5,""),IF(ISNUMBER(SEARCH('Référentiel entourage'!$B$6,_xlpm.texte)),'Référentiel entourage'!$A$6,""),IF(ISNUMBER(SEARCH('Référentiel entourage'!$B$7,_xlpm.texte)),'Référentiel entourage'!$A$7,""),IF(ISNUMBER(SEARCH('Référentiel entourage'!$B$8,_xlpm.texte)),'Référentiel entourage'!$A$8,""),IF(ISNUMBER(SEARCH('Référentiel entourage'!$B$9,_xlpm.texte)),'Référentiel entourage'!$A$9,""),IF(ISNUMBER(SEARCH('Référentiel entourage'!$B$10,_xlpm.texte)),'Référentiel entourage'!$A$10,""),IF(ISNUMBER(SEARCH('Référentiel entourage'!$B$11,_xlpm.texte)),'Référentiel entourage'!$A$11,""),IF(ISNUMBER(SEARCH('Référentiel entourage'!$B$12,_xlpm.texte)),'Référentiel entourage'!$A$12,""),IF(ISNUMBER(SEARCH('Référentiel entourage'!$B$13,_xlpm.texte)),'Référentiel entourage'!$A$13,""),IF(ISNUMBER(SEARCH('Référentiel entourage'!$B$14,_xlpm.texte)),'Référentiel entourage'!$A$14,""),IF(ISNUMBER(SEARCH('Référentiel entourage'!$B$15,_xlpm.texte)),'Référentiel entourage'!$A$15,""),IF(ISNUMBER(SEARCH('Référentiel entourage'!$B$16,_xlpm.texte)),'Référentiel entourage'!$A$16,""),IF(ISNUMBER(SEARCH('Référentiel entourage'!$B$17,_xlpm.texte)),'Référentiel entourage'!$A$17,""),IF(ISNUMBER(SEARCH('Référentiel entourage'!$B$18,_xlpm.texte)),'Référentiel entourage'!$A$18,""),IF(ISNUMBER(SEARCH('Référentiel entourage'!$B$19,_xlpm.texte)),'Référentiel entourage'!$A$19,""),IF(ISNUMBER(SEARCH('Référentiel entourage'!$B$20,_xlpm.texte)),'Référentiel entourage'!$A$20,""),IF(ISNUMBER(SEARCH('Référentiel entourage'!$B$21,_xlpm.texte)),'Référentiel entourage'!$A$21,""),IF(ISNUMBER(SEARCH('Référentiel entourage'!$B$22,_xlpm.texte)),'Référentiel entourage'!$A$22,""),IF(ISNUMBER(SEARCH('Référentiel entourage'!$B$23,_xlpm.texte)),'Référentiel entourage'!$A$23,""),IF(ISNUMBER(SEARCH('Référentiel entourage'!$B$24,_xlpm.texte)),'Référentiel entourage'!$A$24,"")))) -> pers-ulli-lommel; pers-peer-raben
A6: rwf-1969-katzelmacher | B6: Le Bouc | C6: Katzelmacher | D6: 1969 | E6: Long métrage | F6: 88 | G6: RFA | H6: Rainer Werner Fassbinder | I6: Rainer Werner Fassbinder | J6: Dietrich Lohmann | K6: Rainer Werner Fassbinder | M6: Peer Raben | N6: Peer Raben ; Antiteater-X-Film | O6: Hanna Schygulla : Marie Lilith Ungerer : Helga Rudolf Waldemar Brem : Paul Elga Sorbas : Rosy Doris Mattes : Gunda Irm Hermann : Elisabeth Peter Moland : Peter Rainer Werner Fassbinder : Jorgos Hans Hirschmüller : Erich Harry Baer : Franz Hannes Gromball : Klaus Katrin Schaake : la femme sur la route | P6: Format : noir et blanc, 1,37:1, mono Genre : drame, romance Sortie : 1969 | Q6: Jorgos, travailleur immigré grec, rejoint un groupe de jeunes gens à Munich. Son arrivée suscite hostilité et jalousie ; insulté, il confie à Marie son désir de rentrer chez lui. | S6: Le film dénonce la violence exercée par une société étriquée contre les étrnagers, violence que le personnage principal, d'origine grecque, reconduit avec des individus encore plus dominés que lui. Film à l'esthétique avant-gardiste, brechtienne par son caractère anti-illustionniste. Il est constitué d'une suite de brefs tableaux, d'images figées, de plans fontaux. Les mouvements de caméra sont rares : des travellings latéraux, sans profondeur d'images, conservent une forme de théâtralité à l'image. Comme d'autres films de RWF de la période, Le bouc vise un public qui n'est ni restreint et cinéphile, ni populaire. | U6: Films_images/Le_Bouc.jpg | X6: 1969 | Z6: Wikipédia : https://fr.wikipedia.org/wiki/Le_Bouc | AA6: À compléter | AB6: film-1969-le-bouc | AC6: =IF(O6="","",_xlfn.TEXTJOIN("; ",TRUE,IF(ISNUMBER(SEARCH('Référentiel entourage'!$B$2,O6)),'Référentiel entourage'!$A$2,""),IF(ISNUMBER(SEARCH('Référentiel entourage'!$B$3,O6)),'Référentiel entourage'!$A$3,""),IF(ISNUMBER(SEARCH('Référentiel entourage'!$B$4,O6)),'Référentiel entourage'!$A$4,""),IF(ISNUMBER(SEARCH('Référentiel entourage'!$B$5,O6)),'Référentiel entourage'!$A$5,""),IF(ISNUMBER(SEARCH('Référentiel entourage'!$B$6,O6)),'Référentiel entourage'!$A$6,""),IF(ISNUMBER(SEARCH('Référentiel entourage'!$B$7,O6)),'Référentiel entourage'!$A$7,""),IF(ISNUMBER(SEARCH('Référentiel entourage'!$B$8,O6)),'Référentiel entourage'!$A$8,""),IF(ISNUMBER(SEARCH('Référentiel entourage'!$B$9,O6)),'Référentiel entourage'!$A$9,""),IF(ISNUMBER(SEARCH('Référentiel entourage'!$B$10,O6)),'Référentiel entourage'!$A$10,""),IF(ISNUMBER(SEARCH('Référentiel entourage'!$B$11,O6)),'Référentiel entourage'!$A$11,""),IF(ISNUMBER(SEARCH('Référentiel entourage'!$B$12,O6)),'Référentiel entourage'!$A$12,""),IF(ISNUMBER(SEARCH('Référentiel entourage'!$B$13,O6)),'Référentiel entourage'!$A$13,""),IF(ISNUMBER(SEARCH('Référentiel entourage'!$B$14,O6)),'Référentiel entourage'!$A$14,""),IF(ISNUMBER(SEARCH('Référentiel entourage'!$B$15,O6)),'Référentiel entourage'!$A$15,""),IF(ISNUMBER(SEARCH('Référentiel entourage'!$B$16,O6)),'Référentiel entourage'!$A$16,""),IF(ISNUMBER(SEARCH('Référentiel entourage'!$B$17,O6)),'Référentiel entourage'!$A$17,""),IF(ISNUMBER(SEARCH('Référentiel entourage'!$B$18,O6)),'Référentiel entourage'!$A$18,""),IF(ISNUMBER(SEARCH('Référentiel entourage'!$B$19,O6)),'Référentiel entourage'!$A$19,""),IF(ISNUMBER(SEARCH('Référentiel entourage'!$B$20,O6)),'Référentiel entourage'!$A$20,""),IF(ISNUMBER(SEARCH('Référentiel entourage'!$B$21,O6)),'Référentiel entourage'!$A$21,""),IF(ISNUMBER(SEARCH('Référentiel entourage'!$B$22,O6)),'Référentiel entourage'!$A$22,""),IF(ISNUMBER(SEARCH('Référentiel entourage'!$B$23,O6)),'Référentiel entourage'!$A$23,""),IF(ISNUMBER(SEARCH('Référentiel entourage'!$B$24,O6)),'Référentiel entourage'!$A$24,""))) -> pers-irm-hermann; pers-hanna-schygulla; pers-lilith-ungerer | AD6: =_xlfn.LET(_xlpm.texte,_xlfn.TEXTJOIN(" | ",TRUE,H6:N6,P6),IF(_xlpm.texte="","",_xlfn.TEXTJOIN("; ",TRUE,IF(ISNUMBER(SEARCH('Référentiel entourage'!$B$2,_xlpm.texte)),'Référentiel entourage'!$A$2,""),IF(ISNUMBER(SEARCH('Référentiel entourage'!$B$3,_xlpm.texte)),'Référentiel entourage'!$A$3,""),IF(ISNUMBER(SEARCH('Référentiel entourage'!$B$4,_xlpm.texte)),'Référentiel entourage'!$A$4,""),IF(ISNUMBER(SEARCH('Référentiel entourage'!$B$5,_xlpm.texte)),'Référentiel entourage'!$A$5,""),IF(ISNUMBER(SEARCH('Référentiel entourage'!$B$6,_xlpm.texte)),'Référentiel entourage'!$A$6,""),IF(ISNUMBER(SEARCH('Référentiel entourage'!$B$7,_xlpm.texte)),'Référentiel entourage'!$A$7,""),IF(ISNUMBER(SEARCH('Référentiel entourage'!$B$8,_xlpm.texte)),'Référentiel entourage'!$A$8,""),IF(ISNUMBER(SEARCH('Référentiel entourage'!$B$9,_xlpm.texte)),'Référentiel entourage'!$A$9,""),IF(ISNUMBER(SEARCH('Référentiel entourage'!$B$10,_xlpm.texte)),'Référentiel entourage'!$A$10,""),IF(ISNUMBER(SEARCH('Référentiel entourage'!$B$11,_xlpm.texte)),'Référentiel entourage'!$A$11,""),IF(ISNUMBER(SEARCH('Référentiel entourage'!$B$12,_xlpm.texte)),'Référentiel entourage'!$A$12,""),IF(ISNUMBER(SEARCH('Référentiel entourage'!$B$13,_xlpm.texte)),'Référentiel entourage'!$A$13,""),IF(ISNUMBER(SEARCH('Référentiel entourage'!$B$14,_xlpm.texte)),'Référentiel entourage'!$A$14,""),IF(ISNUMBER(SEARCH('Référentiel entourage'!$B$15,_xlpm.texte)),'Référentiel entourage'!$A$15,""),IF(ISNUMBER(SEARCH('Référentiel entourage'!$B$16,_xlpm.texte)),'Référentiel entourage'!$A$16,""),IF(ISNUMBER(SEARCH('Référentiel entourage'!$B$17,_xlpm.texte)),'Référentiel entourage'!$A$17,""),IF(ISNUMBER(SEARCH('Référentiel entourage'!$B$18,_xlpm.texte)),'Référentiel entourage'!$A$18,""),IF(ISNUMBER(SEARCH('Référentiel entourage'!$B$19,_xlpm.texte)),'Référentiel entourage'!$A$19,""),IF(ISNUMBER(SEARCH('Référentiel entourage'!$B$20,_xlpm.texte)),'Référentiel entourage'!$A$20,""),IF(ISNUMBER(SEARCH('Référentiel entourage'!$B$21,_xlpm.texte)),'Référentiel entourage'!$A$21,""),IF(ISNUMBER(SEARCH('Référentiel entourage'!$B$22,_xlpm.texte)),'Référentiel entourage'!$A$22,""),IF(ISNUMBER(SEARCH('Référentiel entourage'!$B$23,_xlpm.texte)),'Référentiel entourage'!$A$23,""),IF(ISNUMBER(SEARCH('Référentiel entourage'!$B$24,_xlpm.texte)),'Référentiel entourage'!$A$24,"")))) -> pers-peer-raben
A7: rwf-1970-les-dieux-de-la-peste | B7: Les Dieux de la peste | C7: Götter der Pest | D7: 1970 | E7: Long métrage | F7: 91 | G7: RFA | H7: Rainer Werner Fassbinder | I7: Rainer Werner Fassbinder | J7: Dietrich Lohmann | K7: Rainer Werner Fassbinder | L7: Kurt Raab | M7: Peer Raben | N7: Rainer Werner Fassbinder ; Michael Fengler | O7: Hanna Schygulla : Johanna Reiher Margarethe von Trotta : Margarethe Harry Baer : Franz Walsch Günther Kaufmann : Günther Carla Aulalu : Carla Ingrid Caven : Magdalena Fuller Lilith Ungerer : la jeune fille du premier café Katrin Schaake : la propriétaire du deuxième café Hannes Gromball : le directeur du supermarché Jan George : un policier Micha Cochina : Joe Lilo Pempeit : la mère Marian Seidowski : Marian Yaak Karsunke : le commissaire Rainer Werner Fassbinder : l’homme qui achète des revues pornographiques | P7: Format : noir et blanc, 35 mm, 1,37:1, mono Genre : drame Sortie : 1970 | Q7: À sa sortie de prison, le petit escroc Franz Walsch retrouve Joanna. Il recherche le « gorille », vieux gangster qui a assassiné son frère, mais décide néanmoins de refaire équipe avec lui pour un dernier braquage. | U7: Films_images/Les_Dieux_de_la_peste.jpg | X7: 1970 | Z7: Wikipédia : https://fr.wikipedia.org/wiki/Les_Dieux_de_la_peste | AA7: À compléter | AB7: film-1970-les-dieux-de-la-peste | AC7: =IF(O7="","",_xlfn.TEXTJOIN("; ",TRUE,IF(ISNUMBER(SEARCH('Référentiel entourage'!$B$2,O7)),'Référentiel entourage'!$A$2,""),IF(ISNUMBER(SEARCH('Référentiel entourage'!$B$3,O7)),'Référentiel entourage'!$A$3,""),IF(ISNUMBER(SEARCH('Référentiel entourage'!$B$4,O7)),'Référentiel entourage'!$A$4,""),IF(ISNUMBER(SEARCH('Référentiel entourage'!$B$5,O7)),'Référentiel entourage'!$A$5,""),IF(ISNUMBER(SEARCH('Référentiel entourage'!$B$6,O7)),'Référentiel entourage'!$A$6,""),IF(ISNUMBER(SEARCH('Référentiel entourage'!$B$7,O7)),'Référentiel entourage'!$A$7,""),IF(ISNUMBER(SEARCH('Référentiel entourage'!$B$8,O7)),'Référentiel entourage'!$A$8,""),IF(ISNUMBER(SEARCH('Référentiel entourage'!$B$9,O7)),'Référentiel entourage'!$A$9,""),IF(ISNUMBER(SEARCH('Référentiel entourage'!$B$10,O7)),'Référentiel entourage'!$A$10,""),IF(ISNUMBER(SEARCH('Référentiel entourage'!$B$11,O7)),'Référentiel entourage'!$A$11,""),IF(ISNUMBER(SEARCH('Référentiel entourage'!$B$12,O7)),'Référentiel entourage'!$A$12,""),IF(ISNUMBER(SEARCH('Référentiel entourage'!$B$13,O7)),'Référentiel entourage'!$A$13,""),IF(ISNUMBER(SEARCH('Référentiel entourage'!$B$14,O7)),'Référentiel entourage'!$A$14,""),IF(ISNUMBER(SEARCH('Référentiel entourage'!$B$15,O7)),'Référentiel entourage'!$A$15,""),IF(ISNUMBER(SEARCH('Référentiel entourage'!$B$16,O7)),'Référentiel entourage'!$A$16,""),IF(ISNUMBER(SEARCH('Référentiel entourage'!$B$17,O7)),'Référentiel entourage'!$A$17,""),IF(ISNUMBER(SEARCH('Référentiel entourage'!$B$18,O7)),'Référentiel entourage'!$A$18,""),IF(ISNUMBER(SEARCH('Référentiel entourage'!$B$19,O7)),'Référentiel entourage'!$A$19,""),IF(ISNUMBER(SEARCH('Référentiel entourage'!$B$20,O7)),'Référentiel entourage'!$A$20,""),IF(ISNUMBER(SEARCH('Référentiel entourage'!$B$21,O7)),'Référentiel entourage'!$A$21,""),IF(ISNUMBER(SEARCH('Référentiel entourage'!$B$22,O7)),'Référentiel entourage'!$A$22,""),IF(ISNUMBER(SEARCH('Référentiel entourage'!$B$23,O7)),'Référentiel entourage'!$A$23,""),IF(ISNUMBER(SEARCH('Référentiel entourage'!$B$24,O7)),'Référentiel entourage'!$A$24,""))) -> pers-ingrid-caven; pers-lilo-pempeit; pers-gunther-kaufmann; pers-hanna-schygulla; pers-lilith-ungerer | AD7: =_xlfn.LET(_xlpm.texte,_xlfn.TEXTJOIN(" | ",TRUE,H7:N7,P7),IF(_xlpm.texte="","",_xlfn.TEXTJOIN("; ",TRUE,IF(ISNUMBER(SEARCH('Référentiel entourage'!$B$2,_xlpm.texte)),'Référentiel entourage'!$A$2,""),IF(ISNUMBER(SEARCH('Référentiel entourage'!$B$3,_xlpm.texte)),'Référentiel entourage'!$A$3,""),IF(ISNUMBER(SEARCH('Référentiel entourage'!$B$4,_xlpm.texte)),'Référentiel entourage'!$A$4,""),IF(ISNUMBER(SEARCH('Référentiel entourage'!$B$5,_xlpm.texte)),'Référentiel entourage'!$A$5,""),IF(ISNUMBER(SEARCH('Référentiel entourage'!$B$6,_xlpm.texte)),'Référentiel entourage'!$A$6,""),IF(ISNUMBER(SEARCH('Référentiel entourage'!$B$7,_xlpm.texte)),'Référentiel entourage'!$A$7,""),IF(ISNUMBER(SEARCH('Référentiel entourage'!$B$8,_xlpm.texte)),'Référentiel entourage'!$A$8,""),IF(ISNUMBER(SEARCH('Référentiel entourage'!$B$9,_xlpm.texte)),'Référentiel entourage'!$A$9,""),IF(ISNUMBER(SEARCH('Référentiel entourage'!$B$10,_xlpm.texte)),'Référentiel entourage'!$A$10,""),IF(ISNUMBER(SEARCH('Référentiel entourage'!$B$11,_xlpm.texte)),'Référentiel entourage'!$A$11,""),IF(ISNUMBER(SEARCH('Référentiel entourage'!$B$12,_xlpm.texte)),'Référentiel entourage'!$A$12,""),IF(ISNUMBER(SEARCH('Référentiel entourage'!$B$13,_xlpm.texte)),'Référentiel entourage'!$A$13,""),IF(ISNUMBER(SEARCH('Référentiel entourage'!$B$14,_xlpm.texte)),'Référentiel entourage'!$A$14,""),IF(ISNUMBER(SEARCH('Référentiel entourage'!$B$15,_xlpm.texte)),'Référentiel entourage'!$A$15,""),IF(ISNUMBER(SEARCH('Référentiel entourage'!$B$16,_xlpm.texte)),'Référentiel entourage'!$A$16,""),IF(ISNUMBER(SEARCH('Référentiel entourage'!$B$17,_xlpm.texte)),'Référentiel entourage'!$A$17,""),IF(ISNUMBER(SEARCH('Référentiel entourage'!$B$18,_xlpm.texte)),'Référentiel entourage'!$A$18,""),IF(ISNUMBER(SEARCH('Référentiel entourage'!$B$19,_xlpm.texte)),'Référentiel entourage'!$A$19,""),IF(ISNUMBER(SEARCH('Référentiel entourage'!$B$20,_xlpm.texte)),'Référentiel entourage'!$A$20,""),IF(ISNUMBER(SEARCH('Référentiel entourage'!$B$21,_xlpm.texte)),'Référentiel entourage'!$A$21,""),IF(ISNUMBER(SEARCH('Référentiel entourage'!$B$22,_xlpm.texte)),'Référentiel entourage'!$A$22,""),IF(ISNUMBER(SEARCH('Référentiel entourage'!$B$23,_xlpm.texte)),'Référentiel entourage'!$A$23,""),IF(ISNUMBER(SEARCH('Référentiel entourage'!$B$24,_xlpm.texte)),'Référentiel entourage'!$A$24,"")))) -> pers-michael-fengler; pers-kurt-raab; pers-peer-raben
A8: rwf-1970-pourquoi-m-r-est-il-atteint-de-folie-meurtriere | B8: Pourquoi M. R. est-il atteint de folie meurtrière ? | C8: Warum läuft Herr R. Amok? | D8: 1970 | E8: Long métrage | F8: 88 | G8: RFA | H8: Rainer Werner Fassbinder et Michael Fengler | I8: Rainer Werner Fassbinder ; Michael Fengler | J8: Dietrich Lohmann | K8: Rainer Werner Fassbinder ; Michael Fengler | L8: Kurt Raab | M8: Peer Raben | N8: Michael Fengler ; Peer Raben | O8: Kurt Raab : Monsieur R. Lilith Ungerer : Madame R. Lilo Pempeit : une collègue de bureau Franz Maron : le chef Harry Baer : un collègue de bureau Peter Moland : un collègue de bureau Hanna Schygulla : l’amie dans le bar Ingrid Caven : une voisine Peer Raben : un ami Doris Mattes : une voisine Irm Hermann : une voisine Amadeus Fengler : Amadeus, le fils Carla Aulalu : une vendeuse du magasin de disques Eva Pampusch : une vendeuse du magasin de disques Peter Hamm : un commissaire Jochen Pinkert : un commissaire | P8: Format : couleur, 35 mm, 1,37:1, mono Genre : drame Sortie : 1970 | Q8: Le film montre la vie quotidienne de Monsieur R., dessinateur industriel quadragénaire, mari et père de famille. | X8: 1970 | Z8: Wikipédia : https://fr.wikipedia.org/wiki/Pourquoi_monsieur_R._est-il_atteint_de_folie_meurtri%C3%A8re_%3F | AA8: À compléter | AB8: film-1970-pourquoi-m-r-est-il-atteint-de-folie-meurtriere | AC8: =IF(O8="","",_xlfn.TEXTJOIN("; ",TRUE,IF(ISNUMBER(SEARCH('Référentiel entourage'!$B$2,O8)),'Référentiel entourage'!$A$2,""),IF(ISNUMBER(SEARCH('Référentiel entourage'!$B$3,O8)),'Référentiel entourage'!$A$3,""),IF(ISNUMBER(SEARCH('Référentiel entourage'!$B$4,O8)),'Référentiel entourage'!$A$4,""),IF(ISNUMBER(SEARCH('Référentiel entourage'!$B$5,O8)),'Référentiel entourage'!$A$5,""),IF(ISNUMBER(SEARCH('Référentiel entourage'!$B$6,O8)),'Référentiel entourage'!$A$6,""),IF(ISNUMBER(SEARCH('Référentiel entourage'!$B$7,O8)),'Référentiel entourage'!$A$7,""),IF(ISNUMBER(SEARCH('Référentiel entourage'!$B$8,O8)),'Référentiel entourage'!$A$8,""),IF(ISNUMBER(SEARCH('Référentiel entourage'!$B$9,O8)),'Référentiel entourage'!$A$9,""),IF(ISNUMBER(SEARCH('Référentiel entourage'!$B$10,O8)),'Référentiel entourage'!$A$10,""),IF(ISNUMBER(SEARCH('Référentiel entourage'!$B$11,O8)),'Référentiel entourage'!$A$11,""),IF(ISNUMBER(SEARCH('Référentiel entourage'!$B$12,O8)),'Référentiel entourage'!$A$12,""),IF(ISNUMBER(SEARCH('Référentiel entourage'!$B$13,O8)),'Référentiel entourage'!$A$13,""),IF(ISNUMBER(SEARCH('Référentiel entourage'!$B$14,O8)),'Référentiel entourage'!$A$14,""),IF(ISNUMBER(SEARCH('Référentiel entourage'!$B$15,O8)),'Référentiel entourage'!$A$15,""),IF(ISNUMBER(SEARCH('Référentiel entourage'!$B$16,O8)),'Référentiel entourage'!$A$16,""),IF(ISNUMBER(SEARCH('Référentiel entourage'!$B$17,O8)),'Référentiel entourage'!$A$17,""),IF(ISNUMBER(SEARCH('Référentiel entourage'!$B$18,O8)),'Référentiel entourage'!$A$18,""),IF(ISNUMBER(SEARCH('Référentiel entourage'!$B$19,O8)),'Référentiel entourage'!$A$19,""),IF(ISNUMBER(SEARCH('Référentiel entourage'!$B$20,O8)),'Référentiel entourage'!$A$20,""),IF(ISNUMBER(SEARCH('Référentiel entourage'!$B$21,O8)),'Référentiel entourage'!$A$21,""),IF(ISNUMBER(SEARCH('Référentiel entourage'!$B$22,O8)),'Référentiel entourage'!$A$22,""),IF(ISNUMBER(SEARCH('Référentiel entourage'!$B$23,O8)),'Référentiel entourage'!$A$23,""),IF(ISNUMBER(SEARCH('Référentiel entourage'!$B$24,O8)),'Référentiel entourage'!$A$24,""))) -> pers-ingrid-caven; pers-lilo-pempeit; pers-irm-hermann; pers-kurt-raab; pers-peer-raben; pers-hanna-schygulla; pers-lilith-ungerer | AD8: =_xlfn.LET(_xlpm.texte,_xlfn.TEXTJOIN(" | ",TRUE,H8:N8,P8),IF(_xlpm.texte="","",_xlfn.TEXTJOIN("; ",TRUE,IF(ISNUMBER(SEARCH('Référentiel entourage'!$B$2,_xlpm.texte)),'Référentiel entourage'!$A$2,""),IF(ISNUMBER(SEARCH('Référentiel entourage'!$B$3,_xlpm.texte)),'Référentiel entourage'!$A$3,""),IF(ISNUMBER(SEARCH('Référentiel entourage'!$B$4,_xlpm.texte)),'Référentiel entourage'!$A$4,""),IF(ISNUMBER(SEARCH('Référentiel entourage'!$B$5,_xlpm.texte)),'Référentiel entourage'!$A$5,""),IF(ISNUMBER(SEARCH('Référentiel entourage'!$B$6,_xlpm.texte)),'Référentiel entourage'!$A$6,""),IF(ISNUMBER(SEARCH('Référentiel entourage'!$B$7,_xlpm.texte)),'Référentiel entourage'!$A$7,""),IF(ISNUMBER(SEARCH('Référentiel entourage'!$B$8,_xlpm.texte)),'Référentiel entourage'!$A$8,""),IF(ISNUMBER(SEARCH('Référentiel entourage'!$B$9,_xlpm.texte)),'Référentiel entourage'!$A$9,""),IF(ISNUMBER(SEARCH('Référentiel entourage'!$B$10,_xlpm.texte)),'Référentiel entourage'!$A$10,""),IF(ISNUMBER(SEARCH('Référentiel entourage'!$B$11,_xlpm.texte)),'Référentiel entourage'!$A$11,""),IF(ISNUMBER(SEARCH('Référentiel entourage'!$B$12,_xlpm.texte)),'Référentiel entourage'!$A$12,""),IF(ISNUMBER(SEARCH('Référentiel entourage'!$B$13,_xlpm.texte)),'Référentiel entourage'!$A$13,""),IF(ISNUMBER(SEARCH('Référentiel entourage'!$B$14,_xlpm.texte)),'Référentiel entourage'!$A$14,""),IF(ISNUMBER(SEARCH('Référentiel entourage'!$B$15,_xlpm.texte)),'Référentiel entourage'!$A$15,""),IF(ISNUMBER(SEARCH('Référentiel entourage'!$B$16,_xlpm.texte)),'Référentiel entourage'!$A$16,""),IF(ISNUMBER(SEARCH('Référentiel entourage'!$B$17,_xlpm.texte)),'Référentiel entourage'!$A$17,""),IF(ISNUMBER(SEARCH('Référentiel entourage'!$B$18,_xlpm.texte)),'Référentiel entourage'!$A$18,""),IF(ISNUMBER(SEARCH('Référentiel entourage'!$B$19,_xlpm.texte)),'Référentiel entourage'!$A$19,""),IF(ISNUMBER(SEARCH('Référentiel entourage'!$B$20,_xlpm.texte)),'Référentiel entourage'!$A$20,""),IF(ISNUMBER(SEARCH('Référentiel entourage'!$B$21,_xlpm.texte)),'Référentiel entourage'!$A$21,""),IF(ISNUMBER(SEARCH('Référentiel entourage'!$B$22,_xlpm.texte)),'Référentiel entourage'!$A$22,""),IF(ISNUMBER(SEARCH('Référentiel entourage'!$B$23,_xlpm.texte)),'Référentiel entourage'!$A$23,""),IF(ISNUMBER(SEARCH('Référentiel entourage'!$B$24,_xlpm.texte)),'Référentiel entourage'!$A$24,"")))) -> pers-michael-fengler; pers-kurt-raab; pers-peer-raben
A9: rwf-1970-le-soldat-americain | B9: Le Soldat américain | C9: Der amerikanische Soldat | D9: 1970 | E9: Long métrage | F9: 80 | G9: RFA | H9: Rainer Werner Fassbinder | I9: Rainer Werner Fassbinder | J9: Dietrich Lohmann | K9: Thea Eymèsz | L9: Kurt Raab ; Rainer Werner Fassbinder | M9: Peer Raben | N9: Antiteater-X-Film | O9: Karl Scheydt : Richard Murphy, dit Ricky Elga Sorbas : Rosa Jan George : Jan Margarethe von Trotta : la femme de chambre Hark Bohm : Doc Ingrid Caven : la chanteuse Eva Ingeborg Scholz : la mère de Ricky Kurt Raab : le frère de Ricky Marius Aicher : un policier Gustl Datz : le chef de la police Marquard Bohm : le détective privé Rainer Werner Fassbinder : Franz Katrin Schaake : Magdalena Fuller Ulli Lommel : un Tzigane Irm Hermann : une prostituée | P9: Langue : allemand Format : noir et blanc, 35 mm, 1,33:1, mono Tournage : 15 jours en août 1970, Munich Sortie RFA : 9 octobre 1970 (festival), puis 27 novembre 1970 | Q9: À Munich, trois policiers recrutent Ricky, tueur à gages natif de la ville revenu du Vietnam, afin d’éliminer plusieurs personnes. | U9: Films_images/Le_Soldat_americain.jpg | X9: 1970 | Z9: Wikipédia : https://fr.wikipedia.org/wiki/Le_Soldat_am%C3%A9ricain | AA9: À compléter | AB9: film-1970-le-soldat-americain | AC9: =IF(O9="","",_xlfn.TEXTJOIN("; ",TRUE,IF(ISNUMBER(SEARCH('Référentiel entourage'!$B$2,O9)),'Référentiel entourage'!$A$2,""),IF(ISNUMBER(SEARCH('Référentiel entourage'!$B$3,O9)),'Référentiel entourage'!$A$3,""),IF(ISNUMBER(SEARCH('Référentiel entourage'!$B$4,O9)),'Référentiel entourage'!$A$4,""),IF(ISNUMBER(SEARCH('Référentiel entourage'!$B$5,O9)),'Référentiel entourage'!$A$5,""),IF(ISNUMBER(SEARCH('Référentiel entourage'!$B$6,O9)),'Référentiel entourage'!$A$6,""),IF(ISNUMBER(SEARCH('Référentiel entourage'!$B$7,O9)),'Référentiel entourage'!$A$7,""),IF(ISNUMBER(SEARCH('Référentiel entourage'!$B$8,O9)),'Référentiel entourage'!$A$8,""),IF(ISNUMBER(SEARCH('Référentiel entourage'!$B$9,O9)),'Référentiel entourage'!$A$9,""),IF(ISNUMBER(SEARCH('Référentiel entourage'!$B$10,O9)),'Référentiel entourage'!$A$10,""),IF(ISNUMBER(SEARCH('Référentiel entourage'!$B$11,O9)),'Référentiel entourage'!$A$11,""),IF(ISNUMBER(SEARCH('Référentiel entourage'!$B$12,O9)),'Référentiel entourage'!$A$12,""),IF(ISNUMBER(SEARCH('Référentiel entourage'!$B$13,O9)),'Référentiel entourage'!$A$13,""),IF(ISNUMBER(SEARCH('Référentiel entourage'!$B$14,O9)),'Référentiel entourage'!$A$14,""),IF(ISNUMBER(SEARCH('Référentiel entourage'!$B$15,O9)),'Référentiel entourage'!$A$15,""),IF(ISNUMBER(SEARCH('Référentiel entourage'!$B$16,O9)),'Référentiel entourage'!$A$16,""),IF(ISNUMBER(SEARCH('Référentiel entourage'!$B$17,O9)),'Référentiel entourage'!$A$17,""),IF(ISNUMBER(SEARCH('Référentiel entourage'!$B$18,O9)),'Référentiel entourage'!$A$18,""),IF(ISNUMBER(SEARCH('Référentiel entourage'!$B$19,O9)),'Référentiel entourage'!$A$19,""),IF(ISNUMBER(SEARCH('Référentiel entourage'!$B$20,O9)),'Référentiel entourage'!$A$20,""),IF(ISNUMBER(SEARCH('Référentiel entourage'!$B$21,O9)),'Référentiel entourage'!$A$21,""),IF(ISNUMBER(SEARCH('Référentiel entourage'!$B$22,O9)),'Référentiel entourage'!$A$22,""),IF(ISNUMBER(SEARCH('Référentiel entourage'!$B$23,O9)),'Référentiel entourage'!$A$23,""),IF(ISNUMBER(SEARCH('Référentiel entourage'!$B$24,O9)),'Référentiel entourage'!$A$24,""))) -> pers-hark-bohm; pers-ingrid-caven; pers-irm-hermann; pers-ulli-lommel; pers-kurt-raab | AD9: =_xlfn.LET(_xlpm.texte,_xlfn.TEXTJOIN(" | ",TRUE,H9:N9,P9),IF(_xlpm.texte="","",_xlfn.TEXTJOIN("; ",TRUE,IF(ISNUMBER(SEARCH('Référentiel entourage'!$B$2,_xlpm.texte)),'Référentiel entourage'!$A$2,""),IF(ISNUMBER(SEARCH('Référentiel entourage'!$B$3,_xlpm.texte)),'Référentiel entourage'!$A$3,""),IF(ISNUMBER(SEARCH('Référentiel entourage'!$B$4,_xlpm.texte)),'Référentiel entourage'!$A$4,""),IF(ISNUMBER(SEARCH('Référentiel entourage'!$B$5,_xlpm.texte)),'Référentiel entourage'!$A$5,""),IF(ISNUMBER(SEARCH('Référentiel entourage'!$B$6,_xlpm.texte)),'Référentiel entourage'!$A$6,""),IF(ISNUMBER(SEARCH('Référentiel entourage'!$B$7,_xlpm.texte)),'Référentiel entourage'!$A$7,""),IF(ISNUMBER(SEARCH('Référentiel entourage'!$B$8,_xlpm.texte)),'Référentiel entourage'!$A$8,""),IF(ISNUMBER(SEARCH('Référentiel entourage'!$B$9,_xlpm.texte)),'Référentiel entourage'!$A$9,""),IF(ISNUMBER(SEARCH('Référentiel entourage'!$B$10,_xlpm.texte)),'Référentiel entourage'!$A$10,""),IF(ISNUMBER(SEARCH('Référentiel entourage'!$B$11,_xlpm.texte)),'Référentiel entourage'!$A$11,""),IF(ISNUMBER(SEARCH('Référentiel entourage'!$B$12,_xlpm.texte)),'Référentiel entourage'!$A$12,""),IF(ISNUMBER(SEARCH('Référentiel entourage'!$B$13,_xlpm.texte)),'Référentiel entourage'!$A$13,""),IF(ISNUMBER(SEARCH('Référentiel entourage'!$B$14,_xlpm.texte)),'Référentiel entourage'!$A$14,""),IF(ISNUMBER(SEARCH('Référentiel entourage'!$B$15,_xlpm.texte)),'Référentiel entourage'!$A$15,""),IF(ISNUMBER(SEARCH('Référentiel entourage'!$B$16,_xlpm.texte)),'Référentiel entourage'!$A$16,""),IF(ISNUMBER(SEARCH('Référentiel entourage'!$B$17,_xlpm.texte)),'Référentiel entourage'!$A$17,""),IF(ISNUMBER(SEARCH('Référentiel entourage'!$B$18,_xlpm.texte)),'Référentiel entourage'!$A$18,""),IF(ISNUMBER(SEARCH('Référentiel entourage'!$B$19,_xlpm.texte)),'Référentiel entourage'!$A$19,""),IF(ISNUMBER(SEARCH('Référentiel entourage'!$B$20,_xlpm.texte)),'Référentiel entourage'!$A$20,""),IF(ISNUMBER(SEARCH('Référentiel entourage'!$B$21,_xlpm.texte)),'Référentiel entourage'!$A$21,""),IF(ISNUMBER(SEARCH('Référentiel entourage'!$B$22,_xlpm.texte)),'Référentiel entourage'!$A$22,""),IF(ISNUMBER(SEARCH('Référentiel entourage'!$B$23,_xlpm.texte)),'Référentiel entourage'!$A$23,""),IF(ISNUMBER(SEARCH('Référentiel entourage'!$B$24,_xlpm.texte)),'Référentiel entourage'!$A$24,"")))) -> pers-kurt-raab; pers-peer-raben
A10: rwf-1970-le-voyage-a-niklashausen | B10: Le Voyage à Niklashausen | C10: Die Niklashauser Fart | D10: 1970 | E10: Téléfilm | F10: 90 | G10: RFA | H10: Rainer Werner Fassbinder | I10: Rainer Werner Fassbinder ; Michael Fengler | J10: Dietrich Lohmann | K10: Thea Eymèsz ; Rainer Werner Fassbinder | L10: Kurt Raab | M10: Peer Raben | N10: Janus Film und Fernsehen | O10: Michael König : Hans Boehm Hanna Schygulla : Johanna Margit Carstensen : Margarethe Franz Maron : le mari de Margarethe Michael Gordon : Antonio Günther Kaufmann : le chef des fermiers Siggi Graue : le premier paysan Michael Fengler : le deuxième paysan Elga Sorbas : la jeune fille évanouie Carla Aulalu : la jeune fille épileptique Kurt Raab : l’évêque Peter Berling : le bourreau Ingrid Caven : la fille qui crie Peer Raben : Monseigneur Rainer Werner Fassbinder : le moine noir Walter Sedlmayr : le prêtre Günther Rupp : le conseiller Karl Scheydt : un bourgeois de Niklashausen Magdalena Montezuma : Penthésilée | P10: Format : couleur, mono Genre : drame Diffusion : 1970 | X10: 1970 | Z10: Wikipédia : https://fr.wikipedia.org/wiki/Le_Voyage_%C3%A0_Niklashausen | AA10: À compléter | AB10: film-1970-le-voyage-a-niklashausen | AC10: =IF(O10="","",_xlfn.TEXTJOIN("; ",TRUE,IF(ISNUMBER(SEARCH('Référentiel entourage'!$B$2,O10)),'Référentiel entourage'!$A$2,""),IF(ISNUMBER(SEARCH('Référentiel entourage'!$B$3,O10)),'Référentiel entourage'!$A$3,""),IF(ISNUMBER(SEARCH('Référentiel entourage'!$B$4,O10)),'Référentiel entourage'!$A$4,""),IF(ISNUMBER(SEARCH('Référentiel entourage'!$B$5,O10)),'Référentiel entourage'!$A$5,""),IF(ISNUMBER(SEARCH('Référentiel entourage'!$B$6,O10)),'Référentiel entourage'!$A$6,""),IF(ISNUMBER(SEARCH('Référentiel entourage'!$B$7,O10)),'Référentiel entourage'!$A$7,""),IF(ISNUMBER(SEARCH('Référentiel entourage'!$B$8,O10)),'Référentiel entourage'!$A$8,""),IF(ISNUMBER(SEARCH('Référentiel entourage'!$B$9,O10)),'Référentiel entourage'!$A$9,""),IF(ISNUMBER(SEARCH('Référentiel entourage'!$B$10,O10)),'Référentiel entourage'!$A$10,""),IF(ISNUMBER(SEARCH('Référentiel entourage'!$B$11,O10)),'Référentiel entourage'!$A$11,""),IF(ISNUMBER(SEARCH('Référentiel entourage'!$B$12,O10)),'Référentiel entourage'!$A$12,""),IF(ISNUMBER(SEARCH('Référentiel entourage'!$B$13,O10)),'Référentiel entourage'!$A$13,""),IF(ISNUMBER(SEARCH('Référentiel entourage'!$B$14,O10)),'Référentiel entourage'!$A$14,""),IF(ISNUMBER(SEARCH('Référentiel entourage'!$B$15,O10)),'Référentiel entourage'!$A$15,""),IF(ISNUMBER(SEARCH('Référentiel entourage'!$B$16,O10)),'Référentiel entourage'!$A$16,""),IF(ISNUMBER(SEARCH('Référentiel entourage'!$B$17,O10)),'Référentiel entourage'!$A$17,""),IF(ISNUMBER(SEARCH('Référentiel entourage'!$B$18,O10)),'Référentiel entourage'!$A$18,""),IF(ISNUMBER(SEARCH('Référentiel entourage'!$B$19,O10)),'Référentiel entourage'!$A$19,""),IF(ISNUMBER(SEARCH('Référentiel entourage'!$B$20,O10)),'Référentiel entourage'!$A$20,""),IF(ISNUMBER(SEARCH('Référentiel entourage'!$B$21,O10)),'Référentiel entourage'!$A$21,""),IF(ISNUMBER(SEARCH('Référentiel entourage'!$B$22,O10)),'Référentiel entourage'!$A$22,""),IF(ISNUMBER(SEARCH('Référentiel entourage'!$B$23,O10)),'Référentiel entourage'!$A$23,""),IF(ISNUMBER(SEARCH('Référentiel entourage'!$B$24,O10)),'Référentiel entourage'!$A$24,""))) -> pers-margit-carstensen; pers-ingrid-caven; pers-michael-fengler; pers-gunther-kaufmann; pers-kurt-raab; pers-peer-raben; pers-hanna-schygulla | AD10: =_xlfn.LET(_xlpm.texte,_xlfn.TEXTJOIN(" | ",TRUE,H10:N10,P10),IF(_xlpm.texte="","",_xlfn.TEXTJOIN("; ",TRUE,IF(ISNUMBER(SEARCH('Référentiel entourage'!$B$2,_xlpm.texte)),'Référentiel entourage'!$A$2,""),IF(ISNUMBER(SEARCH('Référentiel entourage'!$B$3,_xlpm.texte)),'Référentiel entourage'!$A$3,""),IF(ISNUMBER(SEARCH('Référentiel entourage'!$B$4,_xlpm.texte)),'Référentiel entourage'!$A$4,""),IF(ISNUMBER(SEARCH('Référentiel entourage'!$B$5,_xlpm.texte)),'Référentiel entourage'!$A$5,""),IF(ISNUMBER(SEARCH('Référentiel entourage'!$B$6,_xlpm.texte)),'Référentiel entourage'!$A$6,""),IF(ISNUMBER(SEARCH('Référentiel entourage'!$B$7,_xlpm.texte)),'Référentiel entourage'!$A$7,""),IF(ISNUMBER(SEARCH('Référentiel entourage'!$B$8,_xlpm.texte)),'Référentiel entourage'!$A$8,""),IF(ISNUMBER(SEARCH('Référentiel entourage'!$B$9,_xlpm.texte)),'Référentiel entourage'!$A$9,""),IF(ISNUMBER(SEARCH('Référentiel entourage'!$B$10,_xlpm.texte)),'Référentiel entourage'!$A$10,""),IF(ISNUMBER(SEARCH('Référentiel entourage'!$B$11,_xlpm.texte)),'Référentiel entourage'!$A$11,""),IF(ISNUMBER(SEARCH('Référentiel entourage'!$B$12,_xlpm.texte)),'Référentiel entourage'!$A$12,""),IF(ISNUMBER(SEARCH('Référentiel entourage'!$B$13,_xlpm.texte)),'Référentiel entourage'!$A$13,""),IF(ISNUMBER(SEARCH('Référentiel entourage'!$B$14,_xlpm.texte)),'Référentiel entourage'!$A$14,""),IF(ISNUMBER(SEARCH('Référentiel entourage'!$B$15,_xlpm.texte)),'Référentiel entourage'!$A$15,""),IF(ISNUMBER(SEARCH('Référentiel entourage'!$B$16,_xlpm.texte)),'Référentiel entourage'!$A$16,""),IF(ISNUMBER(SEARCH('Référentiel entourage'!$B$17,_xlpm.texte)),'Référentiel entourage'!$A$17,""),IF(ISNUMBER(SEARCH('Référentiel entourage'!$B$18,_xlpm.texte)),'Référentiel entourage'!$A$18,""),IF(ISNUMBER(SEARCH('Référentiel entourage'!$B$19,_xlpm.texte)),'Référentiel entourage'!$A$19,""),IF(ISNUMBER(SEARCH('Référentiel entourage'!$B$20,_xlpm.texte)),'Référentiel entourage'!$A$20,""),IF(ISNUMBER(SEARCH('Référentiel entourage'!$B$21,_xlpm.texte)),'Référentiel entourage'!$A$21,""),IF(ISNUMBER(SEARCH('Référentiel entourage'!$B$22,_xlpm.texte)),'Référentiel entourage'!$A$22,""),IF(ISNUMBER(SEARCH('Référentiel entourage'!$B$23,_xlpm.texte)),'Référentiel entourage'!$A$23,""),IF(ISNUMBER(SEARCH('Référentiel entourage'!$B$24,_xlpm.texte)),'Référentiel entourage'!$A$24,"")))) -> pers-michael-fengler; pers-kurt-raab; pers-peer-raben
A11: rwf-1970-le-cafe | B11: Le Café | C11: Das Kaffehause | D11: 1970 | E11: Téléfilm | G11: RFA | H11: Rainer Werner Fassbinder
A12: rwf-1970-rio-das-mortes | B12: Rio das mortes | D12: 1970 | E12: Film | F12: 84 | G12: RFA | H12: Rainer Werner Fassbinder | I12: Rainer Werner Fassbinder | J12: Dietrich Lohmann | K12: Thea Eymèsz ; Rainer Werner Fassbinder | L12: Kurt Raab | M12: Peer Raben | N12: Klaus Hellwig ; Peer Raben | O12: Hanna Schygulla : Hanna Michael König : Michel Günther Kaufmann : Günther Katrin Schaake : Katrin Harry Baer : le collègue de Michel Ulli Lommel : le vendeur de voitures Ingrid Caven : une collègue de Hanna Magdalena Montezuma : une collègue de Hanna Kurt Raab : le pompiste Joachim von Mengershausen : Joachim Lilo Pempeit : la mère de Günther Walter Sedlmayr : le secrétaire Rainer Werner Fassbinder : le partenaire de danse de Hanna | P12: Costumes : Kurt Raab Format : couleur, mono Genre : comédie Diffusion : 15 février 1971 | Q12: Michel et Günther, lassés de leur vie monotone, projettent de partir au Pérou et tentent de réunir l’argent nécessaire au voyage. | X12: 1970 | Z12: Wikipédia : https://fr.wikipedia.org/wiki/Rio_das_Mortes | AB12: film-1970-rio-das-mortes
A13: rwf-1971-whity | B13: Whity | D13: 1971 | E13: Long métrage | F13: 95 | G13: RFA | H13: Rainer Werner Fassbinder | I13: Rainer Werner Fassbinder | J13: Michael Ballhaus | K13: Thea Eymèsz ; Rainer Werner Fassbinder | L13: Kurt Raab | M13: Peer Raben | N13: Peter Berling ; Ulli Lommel ; Peer Raben ; Antiteater-X-Film ; Atlantis Film | O13: Günther Kaufmann : Whity Ron Randell : Benjamin Nicholson Hanna Schygulla : Hanna Katrin Schaake : Katherine Nicholson Harry Baer : Davy Nicholson Ulli Lommel : Frank Nicholson Thomas Blanco : le faux médecin mexicain Stefano Capriati : le juge Helga Ballhaus : la femme du juge Elaine Baker : la mère de Whity Mark Salvage : le shérif Kurt Raab : le pianiste Rainer Werner Fassbinder : le client du saloon | P13: Format : couleur, 2,35:1, mono Genre : drame, western Sortie : 1971 | Q13: Dans le sud des États-Unis à la fin du XIXe siècle, Whity, fils illégitime métis du riche Ben Nicholson, vit en esclave dans sa propre famille. Humilié par son père, ses demi-frères et l’épouse de celui-ci, il aspire pourtant à une autre condition et fréquente une danseuse de cabaret. | X13: 1971 | Z13: Wikipédia : https://fr.wikipedia.org/wiki/Whity | AA13: À compléter | AB13: film-1971-whity | AC13: =IF(O13="","",_xlfn.TEXTJOIN("; ",TRUE,IF(ISNUMBER(SEARCH('Référentiel entourage'!$B$2,O13)),'Référentiel entourage'!$A$2,""),IF(ISNUMBER(SEARCH('Référentiel entourage'!$B$3,O13)),'Référentiel entourage'!$A$3,""),IF(ISNUMBER(SEARCH('Référentiel entourage'!$B$4,O13)),'Référentiel entourage'!$A$4,""),IF(ISNUMBER(SEARCH('Référentiel entourage'!$B$5,O13)),'Référentiel entourage'!$A$5,""),IF(ISNUMBER(SEARCH('Référentiel entourage'!$B$6,O13)),'Référentiel entourage'!$A$6,""),IF(ISNUMBER(SEARCH('Référentiel entourage'!$B$7,O13)),'Référentiel entourage'!$A$7,""),IF(ISNUMBER(SEARCH('Référentiel entourage'!$B$8,O13)),'Référentiel entourage'!$A$8,""),IF(ISNUMBER(SEARCH('Référentiel entourage'!$B$9,O13)),'Référentiel entourage'!$A$9,""),IF(ISNUMBER(SEARCH('Référentiel entourage'!$B$10,O13)),'Référentiel entourage'!$A$10,""),IF(ISNUMBER(SEARCH('Référentiel entourage'!$B$11,O13)),'Référentiel entourage'!$A$11,""),IF(ISNUMBER(SEARCH('Référentiel entourage'!$B$12,O13)),'Référentiel entourage'!$A$12,""),IF(ISNUMBER(SEARCH('Référentiel entourage'!$B$13,O13)),'Référentiel entourage'!$A$13,""),IF(ISNUMBER(SEARCH('Référentiel entourage'!$B$14,O13)),'Référentiel entourage'!$A$14,""),IF(ISNUMBER(SEARCH('Référentiel entourage'!$B$15,O13)),'Référentiel entourage'!$A$15,""),IF(ISNUMBER(SEARCH('Référentiel entourage'!$B$16,O13)),'Référentiel entourage'!$A$16,""),IF(ISNUMBER(SEARCH('Référentiel entourage'!$B$17,O13)),'Référentiel entourage'!$A$17,""),IF(ISNUMBER(SEARCH('Référentiel entourage'!$B$18,O13)),'Référentiel entourage'!$A$18,""),IF(ISNUMBER(SEARCH('Référentiel entourage'!$B$19,O13)),'Référentiel entourage'!$A$19,""),IF(ISNUMBER(SEARCH('Référentiel entourage'!$B$20,O13)),'Référentiel entourage'!$A$20,""),IF(ISNUMBER(SEARCH('Référentiel entourage'!$B$21,O13)),'Référentiel entourage'!$A$21,""),IF(ISNUMBER(SEARCH('Référentiel entourage'!$B$22,O13)),'Référentiel entourage'!$A$22,""),IF(ISNUMBER(SEARCH('Référentiel entourage'!$B$23,O13)),'Référentiel entourage'!$A$23,""),IF(ISNUMBER(SEARCH('Référentiel entourage'!$B$24,O13)),'Référentiel entourage'!$A$24,""))) -> pers-gunther-kaufmann; pers-ulli-lommel; pers-kurt-raab; pers-hanna-schygulla | AD13: =_xlfn.LET(_xlpm.texte,_xlfn.TEXTJOIN(" | ",TRUE,H13:N13,P13),IF(_xlpm.texte="","",_xlfn.TEXTJOIN("; ",TRUE,IF(ISNUMBER(SEARCH('Référentiel entourage'!$B$2,_xlpm.texte)),'Référentiel entourage'!$A$2,""),IF(ISNUMBER(SEARCH('Référentiel entourage'!$B$3,_xlpm.texte)),'Référentiel entourage'!$A$3,""),IF(ISNUMBER(SEARCH('Référentiel entourage'!$B$4,_xlpm.texte)),'Référentiel entourage'!$A$4,""),IF(ISNUMBER(SEARCH('Référentiel entourage'!$B$5,_xlpm.texte)),'Référentiel entourage'!$A$5,""),IF(ISNUMBER(SEARCH('Référentiel entourage'!$B$6,_xlpm.texte)),'Référentiel entourage'!$A$6,""),IF(ISNUMBER(SEARCH('Référentiel entourage'!$B$7,_xlpm.texte)),'Référentiel entourage'!$A$7,""),IF(ISNUMBER(SEARCH('Référentiel entourage'!$B$8,_xlpm.texte)),'Référentiel entourage'!$A$8,""),IF(ISNUMBER(SEARCH('Référentiel entourage'!$B$9,_xlpm.texte)),'Référentiel entourage'!$A$9,""),IF(ISNUMBER(SEARCH('Référentiel entourage'!$B$10,_xlpm.texte)),'Référentiel entourage'!$A$10,""),IF(ISNUMBER(SEARCH('Référentiel entourage'!$B$11,_xlpm.texte)),'Référentiel entourage'!$A$11,""),IF(ISNUMBER(SEARCH('Référentiel entourage'!$B$12,_xlpm.texte)),'Référentiel entourage'!$A$12,""),IF(ISNUMBER(SEARCH('Référentiel entourage'!$B$13,_xlpm.texte)),'Référentiel entourage'!$A$13,""),IF(ISNUMBER(SEARCH('Référentiel entourage'!$B$14,_xlpm.texte)),'Référentiel entourage'!$A$14,""),IF(ISNUMBER(SEARCH('Référentiel entourage'!$B$15,_xlpm.texte)),'Référentiel entourage'!$A$15,""),IF(ISNUMBER(SEARCH('Référentiel entourage'!$B$16,_xlpm.texte)),'Référentiel entourage'!$A$16,""),IF(ISNUMBER(SEARCH('Référentiel entourage'!$B$17,_xlpm.texte)),'Référentiel entourage'!$A$17,""),IF(ISNUMBER(SEARCH('Référentiel entourage'!$B$18,_xlpm.texte)),'Référentiel entourage'!$A$18,""),IF(ISNUMBER(SEARCH('Référentiel entourage'!$B$19,_xlpm.texte)),'Référentiel entourage'!$A$19,""),IF(ISNUMBER(SEARCH('Référentiel entourage'!$B$20,_xlpm.texte)),'Référentiel entourage'!$A$20,""),IF(ISNUMBER(SEARCH('Référentiel entourage'!$B$21,_xlpm.texte)),'Référentiel entourage'!$A$21,""),IF(ISNUMBER(SEARCH('Référentiel entourage'!$B$22,_xlpm.texte)),'Référentiel entourage'!$A$22,""),IF(ISNUMBER(SEARCH('Référentiel entourage'!$B$23,_xlpm.texte)),'Référentiel entourage'!$A$23,""),IF(ISNUMBER(SEARCH('Référentiel entourage'!$B$24,_xlpm.texte)),'Référentiel entourage'!$A$24,"")))) -> pers-michael-ballhaus; pers-ulli-lommel; pers-kurt-raab; pers-peer-raben
A14: rwf-1971-prenez-garde-a-la-sainte-putain | B14: Prenez garde à la sainte putain | C14: Warnung vor einer heiligen Nutte | D14: 1971 | E14: Long métrage | F14: 103 | G14: RFA | H14: Rainer Werner Fassbinder | I14: Rainer Werner Fassbinder | J14: Michael Ballhaus | K14: Thea Eymèsz ; Rainer Werner Fassbinder (sous le nom de Franz Walsch) | L14: Kurt Raab | M14: Peer Raben | N14: Peter Berling ; Antiteater-X-Film ; Nova International Films | O14: Lou Castel : Jeff, le metteur en scène Eddie Constantine : lui-même Marquard Bohm : Ricky Hanna Schygulla : Hanna Rainer Werner Fassbinder : Sascha Margarethe von Trotta : la secrétaire de production Katrin Schaake : la script Hannes Fuchs : David Marcella Michelangeli : Margret Karl Scheydt : Manfred Ulli Lommel : Korbinian Kurt Raab : Fred Herb Andress : Coach Benjamin Lev : Candy Monika Teuber : Billi Gianni di Luigi : le caméraman Rudolf Waldemar Brem : le chef éclairagiste Thomas Schieder : Jesus Ingrid Caven : une figurante Harry Baer : le mari de la figurante Magdalena Montezuma : Irm Werner Schroeter : Deiters | P14: Langues : allemand, anglais, français, espagnol Format : couleur Genre : comédie dramatique Sortie : 1971 | Q14: Une équipe de cinéma réunie pour un tournage affronte des difficultés multiples : retard du réalisateur, matériel manquant, jalousies et conflits. | S14: Le cinéma comme espace de pouvoir et de destruction Dans Prenez garde à la sainte putain, Fassbinder met en scène une équipe de tournage immobilisée dans un hôtel espagnol par des difficultés financières. L'attente, les rivalités et les relations affectives révèlent progressivement les tensions qui traversent le collectif cinématographique. L'hôtel devient un espace de surveillance, de désir et de violence, où les rapports professionnels et les relations privées s'entremêlent. Le pouvoir du metteur en scène, incarné par Jeff, repose sur l'autorité, l'humiliation et la menace, mais cette violence révèle aussi son impuissance face aux contraintes économiques et à ses propres dépendances. La mise en scène associe le chaos de la production à une forme fragmentée : saynètes discontinues, corps dispersés, dialogues et conflits qui désagrègent le groupe. La séquence finale du film tourné par l'équipe, Patria o Muerte , introduit cependant une rupture : le désordre laisse place à une composition maîtrisée, à des mouvements de caméra élégants et à une temporalité propre au cinéma. Le film interroge ainsi la contradiction entre la dimension collective de la création cinématographique et les rapports de domination qui l'organisent. Il met en tension la représentation de la violence et sa reproduction dans les conditions mêmes du tournage. La beauté de l'image finale ne résout pas cette contradiction : elle fait apparaître la puissance formelle du cinéma au sein d'un système de relations destructrices. | U14: Films_images/Prenez_garde_a_la_sainte_putain.jpg | X14: 1971 | Z14: Wikipédia : https://fr.wikipedia.org/wiki/Prenez_garde_%C3%A0_la_sainte_putain | AA14: À compléter | AB14: film-1971-prenez-garde-a-la-sainte-putain | AC14: =IF(O14="","",_xlfn.TEXTJOIN("; ",TRUE,IF(ISNUMBER(SEARCH('Référentiel entourage'!$B$2,O14)),'Référentiel entourage'!$A$2,""),IF(ISNUMBER(SEARCH('Référentiel entourage'!$B$3,O14)),'Référentiel entourage'!$A$3,""),IF(ISNUMBER(SEARCH('Référentiel entourage'!$B$4,O14)),'Référentiel entourage'!$A$4,""),IF(ISNUMBER(SEARCH('Référentiel entourage'!$B$5,O14)),'Référentiel entourage'!$A$5,""),IF(ISNUMBER(SEARCH('Référentiel entourage'!$B$6,O14)),'Référentiel entourage'!$A$6,""),IF(ISNUMBER(SEARCH('Référentiel entourage'!$B$7,O14)),'Référentiel entourage'!$A$7,""),IF(ISNUMBER(SEARCH('Référentiel entourage'!$B$8,O14)),'Référentiel entourage'!$A$8,""),IF(ISNUMBER(SEARCH('Référentiel entourage'!$B$9,O14)),'Référentiel entourage'!$A$9,""),IF(ISNUMBER(SEARCH('Référentiel entourage'!$B$10,O14)),'Référentiel entourage'!$A$10,""),IF(ISNUMBER(SEARCH('Référentiel entourage'!$B$11,O14)),'Référentiel entourage'!$A$11,""),IF(ISNUMBER(SEARCH('Référentiel entourage'!$B$12,O14)),'Référentiel entourage'!$A$12,""),IF(ISNUMBER(SEARCH('Référentiel entourage'!$B$13,O14)),'Référentiel entourage'!$A$13,""),IF(ISNUMBER(SEARCH('Référentiel entourage'!$B$14,O14)),'Référentiel entourage'!$A$14,""),IF(ISNUMBER(SEARCH('Référentiel entourage'!$B$15,O14)),'Référentiel entourage'!$A$15,""),IF(ISNUMBER(SEARCH('Référentiel entourage'!$B$16,O14)),'Référentiel entourage'!$A$16,""),IF(ISNUMBER(SEARCH('Référentiel entourage'!$B$17,O14)),'Référentiel entourage'!$A$17,""),IF(ISNUMBER(SEARCH('Référentiel entourage'!$B$18,O14)),'Référentiel entourage'!$A$18,""),IF(ISNUMBER(SEARCH('Référentiel entourage'!$B$19,O14)),'Référentiel entourage'!$A$19,""),IF(ISNUMBER(SEARCH('Référentiel entourage'!$B$20,O14)),'Référentiel entourage'!$A$20,""),IF(ISNUMBER(SEARCH('Référentiel entourage'!$B$21,O14)),'Référentiel entourage'!$A$21,""),IF(ISNUMBER(SEARCH('Référentiel entourage'!$B$22,O14)),'Référentiel entourage'!$A$22,""),IF(ISNUMBER(SEARCH('Référentiel entourage'!$B$23,O14)),'Référentiel entourage'!$A$23,""),IF(ISNUMBER(SEARCH('Référentiel entourage'!$B$24,O14)),'Référentiel entourage'!$A$24,""))) -> pers-ingrid-caven; pers-ulli-lommel; pers-kurt-raab; pers-hanna-schygulla | AD14: =_xlfn.LET(_xlpm.texte,_xlfn.TEXTJOIN(" | ",TRUE,H14:N14,P14),IF(_xlpm.texte="","",_xlfn.TEXTJOIN("; ",TRUE,IF(ISNUMBER(SEARCH('Référentiel entourage'!$B$2,_xlpm.texte)),'Référentiel entourage'!$A$2,""),IF(ISNUMBER(SEARCH('Référentiel entourage'!$B$3,_xlpm.texte)),'Référentiel entourage'!$A$3,""),IF(ISNUMBER(SEARCH('Référentiel entourage'!$B$4,_xlpm.texte)),'Référentiel entourage'!$A$4,""),IF(ISNUMBER(SEARCH('Référentiel entourage'!$B$5,_xlpm.texte)),'Référentiel entourage'!$A$5,""),IF(ISNUMBER(SEARCH('Référentiel entourage'!$B$6,_xlpm.texte)),'Référentiel entourage'!$A$6,""),IF(ISNUMBER(SEARCH('Référentiel entourage'!$B$7,_xlpm.texte)),'Référentiel entourage'!$A$7,""),IF(ISNUMBER(SEARCH('Référentiel entourage'!$B$8,_xlpm.texte)),'Référentiel entourage'!$A$8,""),IF(ISNUMBER(SEARCH('Référentiel entourage'!$B$9,_xlpm.texte)),'Référentiel entourage'!$A$9,""),IF(ISNUMBER(SEARCH('Référentiel entourage'!$B$10,_xlpm.texte)),'Référentiel entourage'!$A$10,""),IF(ISNUMBER(SEARCH('Référentiel entourage'!$B$11,_xlpm.texte)),'Référentiel entourage'!$A$11,""),IF(ISNUMBER(SEARCH('Référentiel entourage'!$B$12,_xlpm.texte)),'Référentiel entourage'!$A$12,""),IF(ISNUMBER(SEARCH('Référentiel entourage'!$B$13,_xlpm.texte)),'Référentiel entourage'!$A$13,""),IF(ISNUMBER(SEARCH('Référentiel entourage'!$B$14,_xlpm.texte)),'Référentiel entourage'!$A$14,""),IF(ISNUMBER(SEARCH('Référentiel entourage'!$B$15,_xlpm.texte)),'Référentiel entourage'!$A$15,""),IF(ISNUMBER(SEARCH('Référentiel entourage'!$B$16,_xlpm.texte)),'Référentiel entourage'!$A$16,""),IF(ISNUMBER(SEARCH('Référentiel entourage'!$B$17,_xlpm.texte)),'Référentiel entourage'!$A$17,""),IF(ISNUMBER(SEARCH('Référentiel entourage'!$B$18,_xlpm.texte)),'Référentiel entourage'!$A$18,""),IF(ISNUMBER(SEARCH('Référentiel entourage'!$B$19,_xlpm.texte)),'Référentiel entourage'!$A$19,""),IF(ISNUMBER(SEARCH('Référentiel entourage'!$B$20,_xlpm.texte)),'Référentiel entourage'!$A$20,""),IF(ISNUMBER(SEARCH('Référentiel entourage'!$B$21,_xlpm.texte)),'Référentiel entourage'!$A$21,""),IF(ISNUMBER(SEARCH('Référentiel entourage'!$B$22,_xlpm.texte)),'Référentiel entourage'!$A$22,""),IF(ISNUMBER(SEARCH('Référentiel entourage'!$B$23,_xlpm.texte)),'Référentiel entourage'!$A$23,""),IF(ISNUMBER(SEARCH('Référentiel entourage'!$B$24,_xlpm.texte)),'Référentiel entourage'!$A$24,"")))) -> pers-michael-ballhaus; pers-kurt-raab; pers-peer-raben
A15: rwf-1971-pionniers-a-ingolstadt | B15: Pionniers à Ingolstadt | C15: Pioniere in Ingolstadt | D15: 1971 | E15: Téléfilm | F15: 84 | G15: RFA | H15: Rainer Werner Fassbinder | I15: Rainer Werner Fassbinder, d’après la pièce de Marieluise Fleisser | J15: Dietrich Lohmann | K15: Thea Eymèsz | L15: Kurt Raab | M15: Peer Raben | N15: Janus Film und Fernsehen ; Antiteater pour la ZDF | O15: Hanna Schygulla : Berta Harry Baer : Karl Irm Hermann : Alma Rudolf Waldemar Brem : Fabian Walter Sedlmayr : le sergent-major Klaus Löwitsch : le sergent Günther Kaufmann : Max Carla Aulalu : Frida Elga Sorbas : Marie Burghard Schlicht : Klaus Günther Krää : Gottfried | P15: Assistant de réalisation : Günther Krää Tournage : 25 jours en novembre 1970, Landsberg-Lech et Munich Diffusion RFA : 8 mai 1973 ; présentation à Cannes : 19 mai 1971 | Q15: Une compagnie de soldats du génie arrive à Ingolstadt pour réparer un pont de bois. Les jeunes femmes de la ville, qui s’ennuient, sont attirées par les soldats et s’engagent avec eux dans des jeux de désir et de sexe. | X15: 1971 | Z15: Wikipédia : https://fr.wikipedia.org/wiki/Pionniers_%C3%A0_Ingolstadt | AA15: À compléter | AB15: film-1971-pionniers-a-ingolstadt | AC15: =IF(O15="","",_xlfn.TEXTJOIN("; ",TRUE,IF(ISNUMBER(SEARCH('Référentiel entourage'!$B$2,O15)),'Référentiel entourage'!$A$2,""),IF(ISNUMBER(SEARCH('Référentiel entourage'!$B$3,O15)),'Référentiel entourage'!$A$3,""),IF(ISNUMBER(SEARCH('Référentiel entourage'!$B$4,O15)),'Référentiel entourage'!$A$4,""),IF(ISNUMBER(SEARCH('Référentiel entourage'!$B$5,O15)),'Référentiel entourage'!$A$5,""),IF(ISNUMBER(SEARCH('Référentiel entourage'!$B$6,O15)),'Référentiel entourage'!$A$6,""),IF(ISNUMBER(SEARCH('Référentiel entourage'!$B$7,O15)),'Référentiel entourage'!$A$7,""),IF(ISNUMBER(SEARCH('Référentiel entourage'!$B$8,O15)),'Référentiel entourage'!$A$8,""),IF(ISNUMBER(SEARCH('Référentiel entourage'!$B$9,O15)),'Référentiel entourage'!$A$9,""),IF(ISNUMBER(SEARCH('Référentiel entourage'!$B$10,O15)),'Référentiel entourage'!$A$10,""),IF(ISNUMBER(SEARCH('Référentiel entourage'!$B$11,O15)),'Référentiel entourage'!$A$11,""),IF(ISNUMBER(SEARCH('Référentiel entourage'!$B$12,O15)),'Référentiel entourage'!$A$12,""),IF(ISNUMBER(SEARCH('Référentiel entourage'!$B$13,O15)),'Référentiel entourage'!$A$13,""),IF(ISNUMBER(SEARCH('Référentiel entourage'!$B$14,O15)),'Référentiel entourage'!$A$14,""),IF(ISNUMBER(SEARCH('Référentiel entourage'!$B$15,O15)),'Référentiel entourage'!$A$15,""),IF(ISNUMBER(SEARCH('Référentiel entourage'!$B$16,O15)),'Référentiel entourage'!$A$16,""),IF(ISNUMBER(SEARCH('Référentiel entourage'!$B$17,O15)),'Référentiel entourage'!$A$17,""),IF(ISNUMBER(SEARCH('Référentiel entourage'!$B$18,O15)),'Référentiel entourage'!$A$18,""),IF(ISNUMBER(SEARCH('Référentiel entourage'!$B$19,O15)),'Référentiel entourage'!$A$19,""),IF(ISNUMBER(SEARCH('Référentiel entourage'!$B$20,O15)),'Référentiel entourage'!$A$20,""),IF(ISNUMBER(SEARCH('Référentiel entourage'!$B$21,O15)),'Référentiel entourage'!$A$21,""),IF(ISNUMBER(SEARCH('Référentiel entourage'!$B$22,O15)),'Référentiel entourage'!$A$22,""),IF(ISNUMBER(SEARCH('Référentiel entourage'!$B$23,O15)),'Référentiel entourage'!$A$23,""),IF(ISNUMBER(SEARCH('Référentiel entourage'!$B$24,O15)),'Référentiel entourage'!$A$24,""))) -> pers-irm-hermann; pers-gunther-kaufmann; pers-hanna-schygulla | AD15: =_xlfn.LET(_xlpm.texte,_xlfn.TEXTJOIN(" | ",TRUE,H15:N15,P15),IF(_xlpm.texte="","",_xlfn.TEXTJOIN("; ",TRUE,IF(ISNUMBER(SEARCH('Référentiel entourage'!$B$2,_xlpm.texte)),'Référentiel entourage'!$A$2,""),IF(ISNUMBER(SEARCH('Référentiel entourage'!$B$3,_xlpm.texte)),'Référentiel entourage'!$A$3,""),IF(ISNUMBER(SEARCH('Référentiel entourage'!$B$4,_xlpm.texte)),'Référentiel entourage'!$A$4,""),IF(ISNUMBER(SEARCH('Référentiel entourage'!$B$5,_xlpm.texte)),'Référentiel entourage'!$A$5,""),IF(ISNUMBER(SEARCH('Référentiel entourage'!$B$6,_xlpm.texte)),'Référentiel entourage'!$A$6,""),IF(ISNUMBER(SEARCH('Référentiel entourage'!$B$7,_xlpm.texte)),'Référentiel entourage'!$A$7,""),IF(ISNUMBER(SEARCH('Référentiel entourage'!$B$8,_xlpm.texte)),'Référentiel entourage'!$A$8,""),IF(ISNUMBER(SEARCH('Référentiel entourage'!$B$9,_xlpm.texte)),'Référentiel entourage'!$A$9,""),IF(ISNUMBER(SEARCH('Référentiel entourage'!$B$10,_xlpm.texte)),'Référentiel entourage'!$A$10,""),IF(ISNUMBER(SEARCH('Référentiel entourage'!$B$11,_xlpm.texte)),'Référentiel entourage'!$A$11,""),IF(ISNUMBER(SEARCH('Référentiel entourage'!$B$12,_xlpm.texte)),'Référentiel entourage'!$A$12,""),IF(ISNUMBER(SEARCH('Référentiel entourage'!$B$13,_xlpm.texte)),'Référentiel entourage'!$A$13,""),IF(ISNUMBER(SEARCH('Référentiel entourage'!$B$14,_xlpm.texte)),'Référentiel entourage'!$A$14,""),IF(ISNUMBER(SEARCH('Référentiel entourage'!$B$15,_xlpm.texte)),'Référentiel entourage'!$A$15,""),IF(ISNUMBER(SEARCH('Référentiel entourage'!$B$16,_xlpm.texte)),'Référentiel entourage'!$A$16,""),IF(ISNUMBER(SEARCH('Référentiel entourage'!$B$17,_xlpm.texte)),'Référentiel entourage'!$A$17,""),IF(ISNUMBER(SEARCH('Référentiel entourage'!$B$18,_xlpm.texte)),'Référentiel entourage'!$A$18,""),IF(ISNUMBER(SEARCH('Référentiel entourage'!$B$19,_xlpm.texte)),'Référentiel entourage'!$A$19,""),IF(ISNUMBER(SEARCH('Référentiel entourage'!$B$20,_xlpm.texte)),'Référentiel entourage'!$A$20,""),IF(ISNUMBER(SEARCH('Référentiel entourage'!$B$21,_xlpm.texte)),'Référentiel entourage'!$A$21,""),IF(ISNUMBER(SEARCH('Référentiel entourage'!$B$22,_xlpm.texte)),'Référentiel entourage'!$A$22,""),IF(ISNUMBER(SEARCH('Référentiel entourage'!$B$23,_xlpm.texte)),'Référentiel entourage'!$A$23,""),IF(ISNUMBER(SEARCH('Référentiel entourage'!$B$24,_xlpm.texte)),'Référentiel entourage'!$A$24,"")))) -> pers-kurt-raab; pers-peer-raben
