Workbook

Sheet Périodes
A1: ID période | B1: Titre période | C1: question directrice | D1: Événement histoire et politique | E1: Contexte culturel | F1: Biographie de Fassbinder | G1: Œuvres | H1: ID films - Œuvres | I1: Analyse et réception critique | J1: Liens | K1: Citation | L1: Image | M1: Legende | N1: Notion
A2: 1945-1946 | B2: Les ruines l'Heure zéro | C2: Le "point zéro" de l'histoire de l'Allemagne d'après-guerre est-il un point zéro pour la vie et l'œuvre de RWF ? | D2: Capitulation du Troisième Reich (mai). L'Allemagne est en ruines (Année Zéro). Début de l'occupation alliée et de l'amnésie collective sur le passé nazi. Le pays et berlin sont partagés en zone sous contrôle des différentes forces alliées. | E2: Le cinéma est en ruines. Période des films de décombres ( Trümmerfilme ) comme Les assassins sont parmi nous (Staudte, 1946). | F2: Naissance de Rainer Werner Fassbinder le 31 mai à Bad Wörishofen, Bavière. | H2: =IF(G2="","",_xlfn.TEXTJOIN("; ",TRUE(),IF(ISNUMBER(SEARCH(SUBSTITUTE('Référentiel films'!$A$2,"’","'"),SUBSTITUTE(G2,"’","'"))),'Référentiel films'!$B$2,""),IF(ISNUMBER(SEARCH(SUBSTITUTE('Référentiel films'!$A$3,"’","'"),SUBSTITUTE(G2,"’","'"))),'Référentiel films'!$B$3,""),IF(ISNUMBER(SEARCH(SUBSTITUTE('Référentiel films'!$A$4,"’","'"),SUBSTITUTE(G2,"’","'"))),'Référentiel films'!$B$4,""),IF(ISNUMBER(SEARCH(SUBSTITUTE('Référentiel films'!$A$5,"’","'"),SUBSTITUTE(G2,"’","'"))),'Référentiel films'!$B$5,""),IF(ISNUMBER(SEARCH(SUBSTITUTE('Référentiel films'!$A$6,"’","'"),SUBSTITUTE(G2,"’","'"))),'Référentiel films'!$B$6,""),IF(ISNUMBER(SEARCH(SUBSTITUTE('Référentiel films'!$A$7,"’","'"),SUBSTITUTE(G2,"’","'"))),'Référentiel films'!$B$7,""),IF(ISNUMBER(SEARCH(SUBSTITUTE('Référentiel films'!$A$8,"’","'"),SUBSTITUTE(G2,"’","'"))),'Référentiel films'!$B$8,""),IF(ISNUMBER(SEARCH(SUBSTITUTE('Référentiel films'!$A$9,"’","'"),SUBSTITUTE(G2,"’","'"))),'Référentiel films'!$B$9,""),IF(ISNUMBER(SEARCH(SUBSTITUTE('Référentiel films'!$A$10,"’","'"),SUBSTITUTE(G2,"’","'"))),'Référentiel films'!$B$10,""),IF(ISNUMBER(SEARCH(SUBSTITUTE('Référentiel films'!$A$11,"’","'"),SUBSTITUTE(G2,"’","'"))),'Référentiel films'!$B$11,""),IF(ISNUMBER(SEARCH(SUBSTITUTE('Référentiel films'!$A$12,"’","'"),SUBSTITUTE(G2,"’","'"))),'Référentiel films'!$B$12,""),IF(ISNUMBER(SEARCH(SUBSTITUTE('Référentiel films'!$A$13,"’","'"),SUBSTITUTE(G2,"’","'"))),'Référentiel films'!$B$13,""),IF(ISNUMBER(SEARCH(SUBSTITUTE('Référentiel films'!$A$14,"’","'"),SUBSTITUTE(G2,"’","'"))),'Référentiel films'!$B$14,""),IF(ISNUMBER(SEARCH(SUBSTITUTE('Référentiel films'!$A$15,"’","'"),SUBSTITUTE(G2,"’","'"))),'Référentiel films'!$B$15,""),IF(ISNUMBER(SEARCH(SUBSTITUTE('Référentiel films'!$A$16,"’","'"),SUBSTITUTE(G2,"’","'"))),'Référentiel films'!$B$16,""),IF(ISNUMBER(SEARCH(SUBSTITUTE('Référentiel films'!$A$17,"’","'"),SUBSTITUTE(G2,"’","'"))),'Référentiel films'!$B$17,""),IF(ISNUMBER(SEARCH(SUBSTITUTE('Référentiel films'!$A$18,"’","'"),SUBSTITUTE(G2,"’","'"))),'Référentiel films'!$B$18,""),IF(ISNUMBER(SEARCH(SUBSTITUTE('Référentiel films'!$A$19,"’","'"),SUBSTITUTE(G2,"’","'"))),'Référentiel films'!$B$19,""),IF(ISNUMBER(SEARCH(SUBSTITUTE('Référentiel films'!$A$20,"’","'"),SUBSTITUTE(G2,"’","'"))),'Référentiel films'!$B$20,""),IF(ISNUMBER(SEARCH(SUBSTITUTE('Référentiel films'!$A$21,"’","'"),SUBSTITUTE(G2,"’","'"))),'Référentiel films'!$B$21,""),IF(ISNUMBER(SEARCH(SUBSTITUTE('Référentiel films'!$A$22,"’","'"),SUBSTITUTE(G2,"’","'"))),'Référentiel films'!$B$22,""),IF(ISNUMBER(SEARCH(SUBSTITUTE('Référentiel films'!$A$23,"’","'"),SUBSTITUTE(G2,"’","'"))),'Référentiel films'!$B$23,""),IF(ISNUMBER(SEARCH(SUBSTITUTE('Référentiel films'!$A$24,"’","'"),SUBSTITUTE(G2,"’","'"))),'Référentiel films'!$B$24,""),IF(ISNUMBER(SEARCH(SUBSTITUTE('Référentiel films'!$A$25,"’","'"),SUBSTITUTE(G2,"’","'"))),'Référentiel films'!$B$25,""),IF(ISNUMBER(SEARCH(SUBSTITUTE('Référentiel films'!$A$26,"’","'"),SUBSTITUTE(G2,"’","'"))),'Référentiel films'!$B$26,""),IF(ISNUMBER(SEARCH(SUBSTITUTE('Référentiel films'!$A$27,"’","'"),SUBSTITUTE(G2,"’","'"))),'Référentiel films'!$B$27,""),IF(ISNUMBER(SEARCH(SUBSTITUTE('Référentiel films'!$A$28,"’","'"),SUBSTITUTE(G2,"’","'"))),'Référentiel films'!$B$28,""),IF(ISNUMBER(SEARCH(SUBSTITUTE('Référentiel films'!$A$29,"’","'"),SUBSTITUTE(G2,"’","'"))),'Référentiel films'!$B$29,""),IF(ISNUMBER(SEARCH(SUBSTITUTE('Référentiel films'!$A$30,"’","'"),SUBSTITUTE(G2,"’","'"))),'Référentiel films'!$B$30,""),IF(ISNUMBER(SEARCH(SUBSTITUTE('Référentiel films'!$A$31,"’","'"),SUBSTITUTE(G2,"’","'"))),'Référentiel films'!$B$31,""),IF(ISNUMBER(SEARCH(SUBSTITUTE('Référentiel films'!$A$32,"’","'"),SUBSTITUTE(G2,"’","'"))),'Référentiel films'!$B$32,""),IF(ISNUMBER(SEARCH(SUBSTITUTE('Référentiel films'!$A$33,"’","'"),SUBSTITUTE(G2,"’","'"))),'Référentiel films'!$B$33,""),IF(ISNUMBER(SEARCH(SUBSTITUTE('Référentiel films'!$A$34,"’","'"),SUBSTITUTE(G2,"’","'"))),'Référentiel films'!$B$34,""),IF(ISNUMBER(SEARCH(SUBSTITUTE('Référentiel films'!$A$35,"’","'"),SUBSTITUTE(G2,"’","'"))),'Référentiel films'!$B$35,""),IF(ISNUMBER(SEARCH(SUBSTITUTE('Référentiel films'!$A$36,"’","'"),SUBSTITUTE(G2,"’","'"))),'Référentiel films'!$B$36,""),IF(ISNUMBER(SEARCH(SUBSTITUTE('Référentiel films'!$A$37,"’","'"),SUBSTITUTE(G2,"’","'"))),'Référentiel films'!$B$37,""),IF(ISNUMBER(SEARCH(SUBSTITUTE('Référentiel films'!$A$38,"’","'"),SUBSTITUTE(G2,"’","'"))),'Référentiel films'!$B$38,""),IF(ISNUMBER(SEARCH(SUBSTITUTE('Référentiel films'!$A$39,"’","'"),SUBSTITUTE(G2,"’","'"))),'Référentiel films'!$B$39,""),IF(ISNUMBER(SEARCH(SUBSTITUTE('Référentiel films'!$A$40,"’","'"),SUBSTITUTE(G2,"’","'"))),'Référentiel films'!$B$40,""),IF(ISNUMBER(SEARCH(SUBSTITUTE('Référentiel films'!$A$41,"’","'"),SUBSTITUTE(G2,"’","'"))),'Référentiel films'!$B$41,""))) | I2: L'œuvre de Fassbinder proposera plus tard une radiographie critique de ce "point zéro" de la nouvelle Allemagne, notamment dans Le mariage de Maria Braun | J2: Les génériques de Fassbinder | K2: "Nous devons nous débarrasser du passé pour construire l'avenir". Konrad Adenauer | L2: Adenauer.jpeg | M2: Adénauer
A3: 1947-1960 | B3: Le miracle économique | C3: Comment l'Allemagne de l'ouest a-t-elle pu devenir une des premières nations industrielles capitalistes et une démocratie alors même qu'elle était marquée par le provincialisme, l'absence de morale et l'hypocrisie ? | D3: Création de la RFA (1949). Ère Adenauer. Miracle économique ( Wirtschaftswunder ) entre 1950 et 1965 l'économie ouest-allemande croît de 8,2% en moyenne (contre 5% en France pendant les 30 glorieuses). La coccinelle de Wolkswagen devient l'emblème du "miracle économique". Les entreprise de taille moyenne constituent la colonne vertébrale de la puissance économique allemande en fournissant les outils spécialisés nécessaires à l'industrie. Parallèmement, l'état développe une politique sociale conservatrice. Réarmement de la RFA (1955). | E3: Domination du "cinéma de papa" ( Papas Kino ) : films de terroir ( Heimatfilm ), comédies légères dépolitisées, films en costumes , comédies musicales obitennent toujours les faveurs du public. Ces genres nés dans les années 10 et 20 ont été très exploités par les nazis. Freddy Quinn, Rocco Granata ou Catharina Valente sont les stars de la culture populaire allemande. Il n'existe presque aucun film allemand des années 50 et 60 qui traite des camps de concentration nazis. Le cinéma allemand de la période s'intéresse peu à l'histoire. | F3: Enfance marquée par le divorce de ses parents (1951) et l'absence du père. Passion précoce pour le cinéma (refuge). Première lecture de Berlin Alexanderplatz vers 14 ans. | H3: =IF(G3="","",_xlfn.TEXTJOIN("; ",TRUE(),IF(ISNUMBER(SEARCH(SUBSTITUTE('Référentiel films'!$A$2,"’","'"),SUBSTITUTE(G3,"’","'"))),'Référentiel films'!$B$2,""),IF(ISNUMBER(SEARCH(SUBSTITUTE('Référentiel films'!$A$3,"’","'"),SUBSTITUTE(G3,"’","'"))),'Référentiel films'!$B$3,""),IF(ISNUMBER(SEARCH(SUBSTITUTE('Référentiel films'!$A$4,"’","'"),SUBSTITUTE(G3,"’","'"))),'Référentiel films'!$B$4,""),IF(ISNUMBER(SEARCH(SUBSTITUTE('Référentiel films'!$A$5,"’","'"),SUBSTITUTE(G3,"’","'"))),'Référentiel films'!$B$5,""),IF(ISNUMBER(SEARCH(SUBSTITUTE('Référentiel films'!$A$6,"’","'"),SUBSTITUTE(G3,"’","'"))),'Référentiel films'!$B$6,""),IF(ISNUMBER(SEARCH(SUBSTITUTE('Référentiel films'!$A$7,"’","'"),SUBSTITUTE(G3,"’","'"))),'Référentiel films'!$B$7,""),IF(ISNUMBER(SEARCH(SUBSTITUTE('Référentiel films'!$A$8,"’","'"),SUBSTITUTE(G3,"’","'"))),'Référentiel films'!$B$8,""),IF(ISNUMBER(SEARCH(SUBSTITUTE('Référentiel films'!$A$9,"’","'"),SUBSTITUTE(G3,"’","'"))),'Référentiel films'!$B$9,""),IF(ISNUMBER(SEARCH(SUBSTITUTE('Référentiel films'!$A$10,"’","'"),SUBSTITUTE(G3,"’","'"))),'Référentiel films'!$B$10,""),IF(ISNUMBER(SEARCH(SUBSTITUTE('Référentiel films'!$A$11,"’","'"),SUBSTITUTE(G3,"’","'"))),'Référentiel films'!$B$11,""),IF(ISNUMBER(SEARCH(SUBSTITUTE('Référentiel films'!$A$12,"’","'"),SUBSTITUTE(G3,"’","'"))),'Référentiel films'!$B$12,""),IF(ISNUMBER(SEARCH(SUBSTITUTE('Référentiel films'!$A$13,"’","'"),SUBSTITUTE(G3,"’","'"))),'Référentiel films'!$B$13,""),IF(ISNUMBER(SEARCH(SUBSTITUTE('Référentiel films'!$A$14,"’","'"),SUBSTITUTE(G3,"’","'"))),'Référentiel films'!$B$14,""),IF(ISNUMBER(SEARCH(SUBSTITUTE('Référentiel films'!$A$15,"’","'"),SUBSTITUTE(G3,"’","'"))),'Référentiel films'!$B$15,""),IF(ISNUMBER(SEARCH(SUBSTITUTE('Référentiel films'!$A$16,"’","'"),SUBSTITUTE(G3,"’","'"))),'Référentiel films'!$B$16,""),IF(ISNUMBER(SEARCH(SUBSTITUTE('Référentiel films'!$A$17,"’","'"),SUBSTITUTE(G3,"’","'"))),'Référentiel films'!$B$17,""),IF(ISNUMBER(SEARCH(SUBSTITUTE('Référentiel films'!$A$18,"’","'"),SUBSTITUTE(G3,"’","'"))),'Référentiel films'!$B$18,""),IF(ISNUMBER(SEARCH(SUBSTITUTE('Référentiel films'!$A$19,"’","'"),SUBSTITUTE(G3,"’","'"))),'Référentiel films'!$B$19,""),IF(ISNUMBER(SEARCH(SUBSTITUTE('Référentiel films'!$A$20,"’","'"),SUBSTITUTE(G3,"’","'"))),'Référentiel films'!$B$20,""),IF(ISNUMBER(SEARCH(SUBSTITUTE('Référentiel films'!$A$21,"’","'"),SUBSTITUTE(G3,"’","'"))),'Référentiel films'!$B$21,""),IF(ISNUMBER(SEARCH(SUBSTITUTE('Référentiel films'!$A$22,"’","'"),SUBSTITUTE(G3,"’","'"))),'Référentiel films'!$B$22,""),IF(ISNUMBER(SEARCH(SUBSTITUTE('Référentiel films'!$A$23,"’","'"),SUBSTITUTE(G3,"’","'"))),'Référentiel films'!$B$23,""),IF(ISNUMBER(SEARCH(SUBSTITUTE('Référentiel films'!$A$24,"’","'"),SUBSTITUTE(G3,"’","'"))),'Référentiel films'!$B$24,""),IF(ISNUMBER(SEARCH(SUBSTITUTE('Référentiel films'!$A$25,"’","'"),SUBSTITUTE(G3,"’","'"))),'Référentiel films'!$B$25,""),IF(ISNUMBER(SEARCH(SUBSTITUTE('Référentiel films'!$A$26,"’","'"),SUBSTITUTE(G3,"’","'"))),'Référentiel films'!$B$26,""),IF(ISNUMBER(SEARCH(SUBSTITUTE('Référentiel films'!$A$27,"’","'"),SUBSTITUTE(G3,"’","'"))),'Référentiel films'!$B$27,""),IF(ISNUMBER(SEARCH(SUBSTITUTE('Référentiel films'!$A$28,"’","'"),SUBSTITUTE(G3,"’","'"))),'Référentiel films'!$B$28,""),IF(ISNUMBER(SEARCH(SUBSTITUTE('Référentiel films'!$A$29,"’","'"),SUBSTITUTE(G3,"’","'"))),'Référentiel films'!$B$29,""),IF(ISNUMBER(SEARCH(SUBSTITUTE('Référentiel films'!$A$30,"’","'"),SUBSTITUTE(G3,"’","'"))),'Référentiel films'!$B$30,""),IF(ISNUMBER(SEARCH(SUBSTITUTE('Référentiel films'!$A$31,"’","'"),SUBSTITUTE(G3,"’","'"))),'Référentiel films'!$B$31,""),IF(ISNUMBER(SEARCH(SUBSTITUTE('Référentiel films'!$A$32,"’","'"),SUBSTITUTE(G3,"’","'"))),'Référentiel films'!$B$32,""),IF(ISNUMBER(SEARCH(SUBSTITUTE('Référentiel films'!$A$33,"’","'"),SUBSTITUTE(G3,"’","'"))),'Référentiel films'!$B$33,""),IF(ISNUMBER(SEARCH(SUBSTITUTE('Référentiel films'!$A$34,"’","'"),SUBSTITUTE(G3,"’","'"))),'Référentiel films'!$B$34,""),IF(ISNUMBER(SEARCH(SUBSTITUTE('Référentiel films'!$A$35,"’","'"),SUBSTITUTE(G3,"’","'"))),'Référentiel films'!$B$35,""),IF(ISNUMBER(SEARCH(SUBSTITUTE('Référentiel films'!$A$36,"’","'"),SUBSTITUTE(G3,"’","'"))),'Référentiel films'!$B$36,""),IF(ISNUMBER(SEARCH(SUBSTITUTE('Référentiel films'!$A$37,"’","'"),SUBSTITUTE(G3,"’","'"))),'Référentiel films'!$B$37,""),IF(ISNUMBER(SEARCH(SUBSTITUTE('Référentiel films'!$A$38,"’","'"),SUBSTITUTE(G3,"’","'"))),'Référentiel films'!$B$38,""),IF(ISNUMBER(SEARCH(SUBSTITUTE('Référentiel films'!$A$39,"’","'"),SUBSTITUTE(G3,"’","'"))),'Référentiel films'!$B$39,""),IF(ISNUMBER(SEARCH(SUBSTITUTE('Référentiel films'!$A$40,"’","'"),SUBSTITUTE(G3,"’","'"))),'Référentiel films'!$B$40,""),IF(ISNUMBER(SEARCH(SUBSTITUTE('Référentiel films'!$A$41,"’","'"),SUBSTITUTE(G3,"’","'"))),'Référentiel films'!$B$41,""))) | I3: Jochen et ses collègues, dans Huit heures ne font pas un jour, incarnent les ouvriers hautement qualifiés qui font la réussite économique de la RFA. L'œuvre de Fassbinder analyse rétrospectivement cette période en mettant à distance le consensus social de la prospérité des années 50 et 60 et en révélant les mensonges du miracle économique. Mais il met aussi en exergue l'optimisme et la vitalité anarchique de cette période où tout est possible (la garderie dans Huit heures ne font pas un jour, l'ascension de Maria Braun) | J3: De l’année zéro au miracle économique|https://youtu.be/BC4BffkWyY8?si=e80MWCLF0K9Fgiub; Jalousie de Catharina Valente|https://youtu.be/-ugDTj7UFtU?si=vzGNySrsaYGKZW0k | L3: l-industrie-de-l-industrie-automobile-l-usine-volkswagen-vue-de-l-interieur-usine-wolfsburg-vers-1950.jpg
A4: 1961-1966 | B4: naissance du Nouveau cinéma allemand | C4: Que serait un cinéma nouveau prenant à bras le corps l'histoire de l'Allemagne et du cinéma, tout en s'en détachant ? | D4: Construction du Mur de Berlin (1961). Procès d'Auschwitz à Francfort (1963-1965). Démission d'Adenauer. Grande Coalition (1966). | E4: Manifeste d'Oberhausen (1962) : naissance du Nouveau Cinéma Allemand. Une nouvelle génération de cinéastes s'affirme et conquiert son indépendance notamment par la création de structures de production indépendantes. Fondation de l'école de cinéma DFFB à Berlin (1966). Cette génération incarne le phénomène de la "société sans père" et "la crise du patriarcat". L'absence ou la défaillance des pères devient un thème récurrent du Nouveau Cinéma allemand. | F4: Échec au concours d'entrée de la DFFB. Rencontre Hanna Schygulla et Irm Hermann dans un cours d'art dramatique. Rejoint l'Action-Theater (1967). | G4: Réalise ses premiers courts métrages : This Night (1966) et Le Clochard (1966). Confrontation de la mémoire de la Shoah. | H4: =IF(G4="","",_xlfn.TEXTJOIN("; ",TRUE(),IF(ISNUMBER(SEARCH(SUBSTITUTE('Référentiel films'!$A$2,"’","'"),SUBSTITUTE(G4,"’","'"))),'Référentiel films'!$B$2,""),IF(ISNUMBER(SEARCH(SUBSTITUTE('Référentiel films'!$A$3,"’","'"),SUBSTITUTE(G4,"’","'"))),'Référentiel films'!$B$3,""),IF(ISNUMBER(SEARCH(SUBSTITUTE('Référentiel films'!$A$4,"’","'"),SUBSTITUTE(G4,"’","'"))),'Référentiel films'!$B$4,""),IF(ISNUMBER(SEARCH(SUBSTITUTE('Référentiel films'!$A$5,"’","'"),SUBSTITUTE(G4,"’","'"))),'Référentiel films'!$B$5,""),IF(ISNUMBER(SEARCH(SUBSTITUTE('Référentiel films'!$A$6,"’","'"),SUBSTITUTE(G4,"’","'"))),'Référentiel films'!$B$6,""),IF(ISNUMBER(SEARCH(SUBSTITUTE('Référentiel films'!$A$7,"’","'"),SUBSTITUTE(G4,"’","'"))),'Référentiel films'!$B$7,""),IF(ISNUMBER(SEARCH(SUBSTITUTE('Référentiel films'!$A$8,"’","'"),SUBSTITUTE(G4,"’","'"))),'Référentiel films'!$B$8,""),IF(ISNUMBER(SEARCH(SUBSTITUTE('Référentiel films'!$A$9,"’","'"),SUBSTITUTE(G4,"’","'"))),'Référentiel films'!$B$9,""),IF(ISNUMBER(SEARCH(SUBSTITUTE('Référentiel films'!$A$10,"’","'"),SUBSTITUTE(G4,"’","'"))),'Référentiel films'!$B$10,""),IF(ISNUMBER(SEARCH(SUBSTITUTE('Référentiel films'!$A$11,"’","'"),SUBSTITUTE(G4,"’","'"))),'Référentiel films'!$B$11,""),IF(ISNUMBER(SEARCH(SUBSTITUTE('Référentiel films'!$A$12,"’","'"),SUBSTITUTE(G4,"’","'"))),'Référentiel films'!$B$12,""),IF(ISNUMBER(SEARCH(SUBSTITUTE('Référentiel films'!$A$13,"’","'"),SUBSTITUTE(G4,"’","'"))),'Référentiel films'!$B$13,""),IF(ISNUMBER(SEARCH(SUBSTITUTE('Référentiel films'!$A$14,"’","'"),SUBSTITUTE(G4,"’","'"))),'Référentiel films'!$B$14,""),IF(ISNUMBER(SEARCH(SUBSTITUTE('Référentiel films'!$A$15,"’","'"),SUBSTITUTE(G4,"’","'"))),'Référentiel films'!$B$15,""),IF(ISNUMBER(SEARCH(SUBSTITUTE('Référentiel films'!$A$16,"’","'"),SUBSTITUTE(G4,"’","'"))),'Référentiel films'!$B$16,""),IF(ISNUMBER(SEARCH(SUBSTITUTE('Référentiel films'!$A$17,"’","'"),SUBSTITUTE(G4,"’","'"))),'Référentiel films'!$B$17,""),IF(ISNUMBER(SEARCH(SUBSTITUTE('Référentiel films'!$A$18,"’","'"),SUBSTITUTE(G4,"’","'"))),'Référentiel films'!$B$18,""),IF(ISNUMBER(SEARCH(SUBSTITUTE('Référentiel films'!$A$19,"’","'"),SUBSTITUTE(G4,"’","'"))),'Référentiel films'!$B$19,""),IF(ISNUMBER(SEARCH(SUBSTITUTE('Référentiel films'!$A$20,"’","'"),SUBSTITUTE(G4,"’","'"))),'Référentiel films'!$B$20,""),IF(ISNUMBER(SEARCH(SUBSTITUTE('Référentiel films'!$A$21,"’","'"),SUBSTITUTE(G4,"’","'"))),'Référentiel films'!$B$21,""),IF(ISNUMBER(SEARCH(SUBSTITUTE('Référentiel films'!$A$22,"’","'"),SUBSTITUTE(G4,"’","'"))),'Référentiel films'!$B$22,""),IF(ISNUMBER(SEARCH(SUBSTITUTE('Référentiel films'!$A$23,"’","'"),SUBSTITUTE(G4,"’","'"))),'Référentiel films'!$B$23,""),IF(ISNUMBER(SEARCH(SUBSTITUTE('Référentiel films'!$A$24,"’","'"),SUBSTITUTE(G4,"’","'"))),'Référentiel films'!$B$24,""),IF(ISNUMBER(SEARCH(SUBSTITUTE('Référentiel films'!$A$25,"’","'"),SUBSTITUTE(G4,"’","'"))),'Référentiel films'!$B$25,""),IF(ISNUMBER(SEARCH(SUBSTITUTE('Référentiel films'!$A$26,"’","'"),SUBSTITUTE(G4,"’","'"))),'Référentiel films'!$B$26,""),IF(ISNUMBER(SEARCH(SUBSTITUTE('Référentiel films'!$A$27,"’","'"),SUBSTITUTE(G4,"’","'"))),'Référentiel films'!$B$27,""),IF(ISNUMBER(SEARCH(SUBSTITUTE('Référentiel films'!$A$28,"’","'"),SUBSTITUTE(G4,"’","'"))),'Référentiel films'!$B$28,""),IF(ISNUMBER(SEARCH(SUBSTITUTE('Référentiel films'!$A$29,"’","'"),SUBSTITUTE(G4,"’","'"))),'Référentiel films'!$B$29,""),IF(ISNUMBER(SEARCH(SUBSTITUTE('Référentiel films'!$A$30,"’","'"),SUBSTITUTE(G4,"’","'"))),'Référentiel films'!$B$30,""),IF(ISNUMBER(SEARCH(SUBSTITUTE('Référentiel films'!$A$31,"’","'"),SUBSTITUTE(G4,"’","'"))),'Référentiel films'!$B$31,""),IF(ISNUMBER(SEARCH(SUBSTITUTE('Référentiel films'!$A$32,"’","'"),SUBSTITUTE(G4,"’","'"))),'Référentiel films'!$B$32,""),IF(ISNUMBER(SEARCH(SUBSTITUTE('Référentiel films'!$A$33,"’","'"),SUBSTITUTE(G4,"’","'"))),'Référentiel films'!$B$33,""),IF(ISNUMBER(SEARCH(SUBSTITUTE('Référentiel films'!$A$34,"’","'"),SUBSTITUTE(G4,"’","'"))),'Référentiel films'!$B$34,""),IF(ISNUMBER(SEARCH(SUBSTITUTE('Référentiel films'!$A$35,"’","'"),SUBSTITUTE(G4,"’","'"))),'Référentiel films'!$B$35,""),IF(ISNUMBER(SEARCH(SUBSTITUTE('Référentiel films'!$A$36,"’","'"),SUBSTITUTE(G4,"’","'"))),'Référentiel films'!$B$36,""),IF(ISNUMBER(SEARCH(SUBSTITUTE('Référentiel films'!$A$37,"’","'"),SUBSTITUTE(G4,"’","'"))),'Référentiel films'!$B$37,""),IF(ISNUMBER(SEARCH(SUBSTITUTE('Référentiel films'!$A$38,"’","'"),SUBSTITUTE(G4,"’","'"))),'Référentiel films'!$B$38,""),IF(ISNUMBER(SEARCH(SUBSTITUTE('Référentiel films'!$A$39,"’","'"),SUBSTITUTE(G4,"’","'"))),'Référentiel films'!$B$39,""),IF(ISNUMBER(SEARCH(SUBSTITUTE('Référentiel films'!$A$40,"’","'"),SUBSTITUTE(G4,"’","'"))),'Référentiel films'!$B$40,""),IF(ISNUMBER(SEARCH(SUBSTITUTE('Référentiel films'!$A$41,"’","'"),SUBSTITUTE(G4,"’","'"))),'Référentiel films'!$B$41,""))) | J4: Documentaire sur le nouveau cinéma allemand | K4: "Le cinéma de Papa est mort. Nous croyons au nouveau cinéma " Manifeste d'Oberhausen (1962) « Toute une génération exorcisa son enfance déjà presque oubliée en soulignant sans répit combien étaient encombrantes et dévastatrices les ombres que le passé des parents avaient jetées sur le présent de leurs enfants ».Thomas Elsaesser, RWF un cinéaste d'Allemagne (2005) p.201
A5: 1967-1970 | B5: Antitheater et politisation | C5: Qu'-est-ce qu'un cinéaste engagé ? | D5: Mouvements étudiants de 1968. Tentative d'assassinat contre Rudi Dutschke. Victoire de Willy Brandt (SPD, 1969). Abrogation partielle de l'article 175 (homosexualité). | F5: Fonde l' antiteater (1968). Collaboration intense avec sa "troupe" (Schygulla, Hermann, Raab, Baer, Lommel). Mariage avec Ingrid Caven (1970). | G5: L'amour est plus froid que la mort (1969), Le Bouc (1969) | H5: =IF(G5="","",_xlfn.TEXTJOIN("; ",TRUE(),IF(ISNUMBER(SEARCH(SUBSTITUTE('Référentiel films'!$A$2,"’","'"),SUBSTITUTE(G5,"’","'"))),'Référentiel films'!$B$2,""),IF(ISNUMBER(SEARCH(SUBSTITUTE('Référentiel films'!$A$3,"’","'"),SUBSTITUTE(G5,"’","'"))),'Référentiel films'!$B$3,""),IF(ISNUMBER(SEARCH(SUBSTITUTE('Référentiel films'!$A$4,"’","'"),SUBSTITUTE(G5,"’","'"))),'Référentiel films'!$B$4,""),IF(ISNUMBER(SEARCH(SUBSTITUTE('Référentiel films'!$A$5,"’","'"),SUBSTITUTE(G5,"’","'"))),'Référentiel films'!$B$5,""),IF(ISNUMBER(SEARCH(SUBSTITUTE('Référentiel films'!$A$6,"’","'"),SUBSTITUTE(G5,"’","'"))),'Référentiel films'!$B$6,""),IF(ISNUMBER(SEARCH(SUBSTITUTE('Référentiel films'!$A$7,"’","'"),SUBSTITUTE(G5,"’","'"))),'Référentiel films'!$B$7,""),IF(ISNUMBER(SEARCH(SUBSTITUTE('Référentiel films'!$A$8,"’","'"),SUBSTITUTE(G5,"’","'"))),'Référentiel films'!$B$8,""),IF(ISNUMBER(SEARCH(SUBSTITUTE('Référentiel films'!$A$9,"’","'"),SUBSTITUTE(G5,"’","'"))),'Référentiel films'!$B$9,""),IF(ISNUMBER(SEARCH(SUBSTITUTE('Référentiel films'!$A$10,"’","'"),SUBSTITUTE(G5,"’","'"))),'Référentiel films'!$B$10,""),IF(ISNUMBER(SEARCH(SUBSTITUTE('Référentiel films'!$A$11,"’","'"),SUBSTITUTE(G5,"’","'"))),'Référentiel films'!$B$11,""),IF(ISNUMBER(SEARCH(SUBSTITUTE('Référentiel films'!$A$12,"’","'"),SUBSTITUTE(G5,"’","'"))),'Référentiel films'!$B$12,""),IF(ISNUMBER(SEARCH(SUBSTITUTE('Référentiel films'!$A$13,"’","'"),SUBSTITUTE(G5,"’","'"))),'Référentiel films'!$B$13,""),IF(ISNUMBER(SEARCH(SUBSTITUTE('Référentiel films'!$A$14,"’","'"),SUBSTITUTE(G5,"’","'"))),'Référentiel films'!$B$14,""),IF(ISNUMBER(SEARCH(SUBSTITUTE('Référentiel films'!$A$15,"’","'"),SUBSTITUTE(G5,"’","'"))),'Référentiel films'!$B$15,""),IF(ISNUMBER(SEARCH(SUBSTITUTE('Référentiel films'!$A$16,"’","'"),SUBSTITUTE(G5,"’","'"))),'Référentiel films'!$B$16,""),IF(ISNUMBER(SEARCH(SUBSTITUTE('Référentiel films'!$A$17,"’","'"),SUBSTITUTE(G5,"’","'"))),'Référentiel films'!$B$17,""),IF(ISNUMBER(SEARCH(SUBSTITUTE('Référentiel films'!$A$18,"’","'"),SUBSTITUTE(G5,"’","'"))),'Référentiel films'!$B$18,""),IF(ISNUMBER(SEARCH(SUBSTITUTE('Référentiel films'!$A$19,"’","'"),SUBSTITUTE(G5,"’","'"))),'Référentiel films'!$B$19,""),IF(ISNUMBER(SEARCH(SUBSTITUTE('Référentiel films'!$A$20,"’","'"),SUBSTITUTE(G5,"’","'"))),'Référentiel films'!$B$20,""),IF(ISNUMBER(SEARCH(SUBSTITUTE('Référentiel films'!$A$21,"’","'"),SUBSTITUTE(G5,"’","'"))),'Référentiel films'!$B$21,""),IF(ISNUMBER(SEARCH(SUBSTITUTE('Référentiel films'!$A$22,"’","'"),SUBSTITUTE(G5,"’","'"))),'Référentiel films'!$B$22,""),IF(ISNUMBER(SEARCH(SUBSTITUTE('Référentiel films'!$A$23,"’","'"),SUBSTITUTE(G5,"’","'"))),'Référentiel films'!$B$23,""),IF(ISNUMBER(SEARCH(SUBSTITUTE('Référentiel films'!$A$24,"’","'"),SUBSTITUTE(G5,"’","'"))),'Référentiel films'!$B$24,""),IF(ISNUMBER(SEARCH(SUBSTITUTE('Référentiel films'!$A$25,"’","'"),SUBSTITUTE(G5,"’","'"))),'Référentiel films'!$B$25,""),IF(ISNUMBER(SEARCH(SUBSTITUTE('Référentiel films'!$A$26,"’","'"),SUBSTITUTE(G5,"’","'"))),'Référentiel films'!$B$26,""),IF(ISNUMBER(SEARCH(SUBSTITUTE('Référentiel films'!$A$27,"’","'"),SUBSTITUTE(G5,"’","'"))),'Référentiel films'!$B$27,""),IF(ISNUMBER(SEARCH(SUBSTITUTE('Référentiel films'!$A$28,"’","'"),SUBSTITUTE(G5,"’","'"))),'Référentiel films'!$B$28,""),IF(ISNUMBER(SEARCH(SUBSTITUTE('Référentiel films'!$A$29,"’","'"),SUBSTITUTE(G5,"’","'"))),'Référentiel films'!$B$29,""),IF(ISNUMBER(SEARCH(SUBSTITUTE('Référentiel films'!$A$30,"’","'"),SUBSTITUTE(G5,"’","'"))),'Référentiel films'!$B$30,""),IF(ISNUMBER(SEARCH(SUBSTITUTE('Référentiel films'!$A$31,"’","'"),SUBSTITUTE(G5,"’","'"))),'Référentiel films'!$B$31,""),IF(ISNUMBER(SEARCH(SUBSTITUTE('Référentiel films'!$A$32,"’","'"),SUBSTITUTE(G5,"’","'"))),'Référentiel films'!$B$32,""),IF(ISNUMBER(SEARCH(SUBSTITUTE('Référentiel films'!$A$33,"’","'"),SUBSTITUTE(G5,"’","'"))),'Référentiel films'!$B$33,""),IF(ISNUMBER(SEARCH(SUBSTITUTE('Référentiel films'!$A$34,"’","'"),SUBSTITUTE(G5,"’","'"))),'Référentiel films'!$B$34,""),IF(ISNUMBER(SEARCH(SUBSTITUTE('Référentiel films'!$A$35,"’","'"),SUBSTITUTE(G5,"’","'"))),'Référentiel films'!$B$35,""),IF(ISNUMBER(SEARCH(SUBSTITUTE('Référentiel films'!$A$36,"’","'"),SUBSTITUTE(G5,"’","'"))),'Référentiel films'!$B$36,""),IF(ISNUMBER(SEARCH(SUBSTITUTE('Référentiel films'!$A$37,"’","'"),SUBSTITUTE(G5,"’","'"))),'Référentiel films'!$B$37,""),IF(ISNUMBER(SEARCH(SUBSTITUTE('Référentiel films'!$A$38,"’","'"),SUBSTITUTE(G5,"’","'"))),'Référentiel films'!$B$38,""),IF(ISNUMBER(SEARCH(SUBSTITUTE('Référentiel films'!$A$39,"’","'"),SUBSTITUTE(G5,"’","'"))),'Référentiel films'!$B$39,""),IF(ISNUMBER(SEARCH(SUBSTITUTE('Référentiel films'!$A$40,"’","'"),SUBSTITUTE(G5,"’","'"))),'Référentiel films'!$B$40,""),IF(ISNUMBER(SEARCH(SUBSTITUTE('Référentiel films'!$A$41,"’","'"),SUBSTITUTE(G5,"’","'"))),'Référentiel films'!$B$41,""))) -> film-1969-l-amour-est-plus-froid-que-la-mort; film-1969-le-bouc | I5: Le bouc est un tournant tant en termes de reconnaissance que du point de vue économique. Le film aborde des problématiques contemporaines (sort des travailleurs immigrés) et des thématiques chères à RWF (l'univers étriqué de la bourgeoisie, en particulière bavaroise).
A6: 1971-1974 | B6: Terrorisme et mélodrame | C6: Comment faire du cinéma allemand hollywoodien, qui attire et séduise le public le plus large tout en l'amenant à l'analyse et à la réflexion, sans didactisme ? | D6: Terrorisme de la RAF (arrestations en 1972). Attentat des JO de Munich (1972). Démission de Willy Brandt (1974) suite à l'affaire Guillaume. | E6: Fondation du Filmverlag der Autoren (1971). Accords Film-Télévision (1974) favorisant les coproductions (WDR). Plusieurs cinéastes allemands ( Schlöndorff, Herzog notamment) réalisent des charges politiques violentes contre la politique et la société allemande. Pourtant l'amnnésie historique se poursuit dans le cinéma allemand de fiction. Seuls des documentaires s'emparent de l'histoire du nazisme. A parti de 1968 l'industrie du cinéma commercial allemand agonise | F6: Découverte des mélodrames de Douglas Sirk grâce à Peer Raben .Liaison avec El Hedi ben Salem. Direction du TAT à Francfort. Collaboration avec le caméraman Michael Ballhaus. Succès international. Les films de RWF deviennent incontournables dans les grands festivals internationaux (Cannes, Venise, Berlin). | G6: Période Sirkienne : Le Marchand des quatre saisons (1971). Tous les autres s'appellent Ali (1974, succès mondial à Cannes) : critique du racisme ordinaire. Martha (1974). | H6: =IF(G6="","",_xlfn.TEXTJOIN("; ",TRUE(),IF(ISNUMBER(SEARCH(SUBSTITUTE('Référentiel films'!$A$2,"’","'"),SUBSTITUTE(G6,"’","'"))),'Référentiel films'!$B$2,""),IF(ISNUMBER(SEARCH(SUBSTITUTE('Référentiel films'!$A$3,"’","'"),SUBSTITUTE(G6,"’","'"))),'Référentiel films'!$B$3,""),IF(ISNUMBER(SEARCH(SUBSTITUTE('Référentiel films'!$A$4,"’","'"),SUBSTITUTE(G6,"’","'"))),'Référentiel films'!$B$4,""),IF(ISNUMBER(SEARCH(SUBSTITUTE('Référentiel films'!$A$5,"’","'"),SUBSTITUTE(G6,"’","'"))),'Référentiel films'!$B$5,""),IF(ISNUMBER(SEARCH(SUBSTITUTE('Référentiel films'!$A$6,"’","'"),SUBSTITUTE(G6,"’","'"))),'Référentiel films'!$B$6,""),IF(ISNUMBER(SEARCH(SUBSTITUTE('Référentiel films'!$A$7,"’","'"),SUBSTITUTE(G6,"’","'"))),'Référentiel films'!$B$7,""),IF(ISNUMBER(SEARCH(SUBSTITUTE('Référentiel films'!$A$8,"’","'"),SUBSTITUTE(G6,"’","'"))),'Référentiel films'!$B$8,""),IF(ISNUMBER(SEARCH(SUBSTITUTE('Référentiel films'!$A$9,"’","'"),SUBSTITUTE(G6,"’","'"))),'Référentiel films'!$B$9,""),IF(ISNUMBER(SEARCH(SUBSTITUTE('Référentiel films'!$A$10,"’","'"),SUBSTITUTE(G6,"’","'"))),'Référentiel films'!$B$10,""),IF(ISNUMBER(SEARCH(SUBSTITUTE('Référentiel films'!$A$11,"’","'"),SUBSTITUTE(G6,"’","'"))),'Référentiel films'!$B$11,""),IF(ISNUMBER(SEARCH(SUBSTITUTE('Référentiel films'!$A$12,"’","'"),SUBSTITUTE(G6,"’","'"))),'Référentiel films'!$B$12,""),IF(ISNUMBER(SEARCH(SUBSTITUTE('Référentiel films'!$A$13,"’","'"),SUBSTITUTE(G6,"’","'"))),'Référentiel films'!$B$13,""),IF(ISNUMBER(SEARCH(SUBSTITUTE('Référentiel films'!$A$14,"’","'"),SUBSTITUTE(G6,"’","'"))),'Référentiel films'!$B$14,""),IF(ISNUMBER(SEARCH(SUBSTITUTE('Référentiel films'!$A$15,"’","'"),SUBSTITUTE(G6,"’","'"))),'Référentiel films'!$B$15,""),IF(ISNUMBER(SEARCH(SUBSTITUTE('Référentiel films'!$A$16,"’","'"),SUBSTITUTE(G6,"’","'"))),'Référentiel films'!$B$16,""),IF(ISNUMBER(SEARCH(SUBSTITUTE('Référentiel films'!$A$17,"’","'"),SUBSTITUTE(G6,"’","'"))),'Référentiel films'!$B$17,""),IF(ISNUMBER(SEARCH(SUBSTITUTE('Référentiel films'!$A$18,"’","'"),SUBSTITUTE(G6,"’","'"))),'Référentiel films'!$B$18,""),IF(ISNUMBER(SEARCH(SUBSTITUTE('Référentiel films'!$A$19,"’","'"),SUBSTITUTE(G6,"’","'"))),'Référentiel films'!$B$19,""),IF(ISNUMBER(SEARCH(SUBSTITUTE('Référentiel films'!$A$20,"’","'"),SUBSTITUTE(G6,"’","'"))),'Référentiel films'!$B$20,""),IF(ISNUMBER(SEARCH(SUBSTITUTE('Référentiel films'!$A$21,"’","'"),SUBSTITUTE(G6,"’","'"))),'Référentiel films'!$B$21,""),IF(ISNUMBER(SEARCH(SUBSTITUTE('Référentiel films'!$A$22,"’","'"),SUBSTITUTE(G6,"’","'"))),'Référentiel films'!$B$22,""),IF(ISNUMBER(SEARCH(SUBSTITUTE('Référentiel films'!$A$23,"’","'"),SUBSTITUTE(G6,"’","'"))),'Référentiel films'!$B$23,""),IF(ISNUMBER(SEARCH(SUBSTITUTE('Référentiel films'!$A$24,"’","'"),SUBSTITUTE(G6,"’","'"))),'Référentiel films'!$B$24,""),IF(ISNUMBER(SEARCH(SUBSTITUTE('Référentiel films'!$A$25,"’","'"),SUBSTITUTE(G6,"’","'"))),'Référentiel films'!$B$25,""),IF(ISNUMBER(SEARCH(SUBSTITUTE('Référentiel films'!$A$26,"’","'"),SUBSTITUTE(G6,"’","'"))),'Référentiel films'!$B$26,""),IF(ISNUMBER(SEARCH(SUBSTITUTE('Référentiel films'!$A$27,"’","'"),SUBSTITUTE(G6,"’","'"))),'Référentiel films'!$B$27,""),IF(ISNUMBER(SEARCH(SUBSTITUTE('Référentiel films'!$A$28,"’","'"),SUBSTITUTE(G6,"’","'"))),'Référentiel films'!$B$28,""),IF(ISNUMBER(SEARCH(SUBSTITUTE('Référentiel films'!$A$29,"’","'"),SUBSTITUTE(G6,"’","'"))),'Référentiel films'!$B$29,""),IF(ISNUMBER(SEARCH(SUBSTITUTE('Référentiel films'!$A$30,"’","'"),SUBSTITUTE(G6,"’","'"))),'Référentiel films'!$B$30,""),IF(ISNUMBER(SEARCH(SUBSTITUTE('Référentiel films'!$A$31,"’","'"),SUBSTITUTE(G6,"’","'"))),'Référentiel films'!$B$31,""),IF(ISNUMBER(SEARCH(SUBSTITUTE('Référentiel films'!$A$32,"’","'"),SUBSTITUTE(G6,"’","'"))),'Référentiel films'!$B$32,""),IF(ISNUMBER(SEARCH(SUBSTITUTE('Référentiel films'!$A$33,"’","'"),SUBSTITUTE(G6,"’","'"))),'Référentiel films'!$B$33,""),IF(ISNUMBER(SEARCH(SUBSTITUTE('Référentiel films'!$A$34,"’","'"),SUBSTITUTE(G6,"’","'"))),'Référentiel films'!$B$34,""),IF(ISNUMBER(SEARCH(SUBSTITUTE('Référentiel films'!$A$35,"’","'"),SUBSTITUTE(G6,"’","'"))),'Référentiel films'!$B$35,""),IF(ISNUMBER(SEARCH(SUBSTITUTE('Référentiel films'!$A$36,"’","'"),SUBSTITUTE(G6,"’","'"))),'Référentiel films'!$B$36,""),IF(ISNUMBER(SEARCH(SUBSTITUTE('Référentiel films'!$A$37,"’","'"),SUBSTITUTE(G6,"’","'"))),'Référentiel films'!$B$37,""),IF(ISNUMBER(SEARCH(SUBSTITUTE('Référentiel films'!$A$38,"’","'"),SUBSTITUTE(G6,"’","'"))),'Référentiel films'!$B$38,""),IF(ISNUMBER(SEARCH(SUBSTITUTE('Référentiel films'!$A$39,"’","'"),SUBSTITUTE(G6,"’","'"))),'Référentiel films'!$B$39,""),IF(ISNUMBER(SEARCH(SUBSTITUTE('Référentiel films'!$A$40,"’","'"),SUBSTITUTE(G6,"’","'"))),'Référentiel films'!$B$40,""),IF(ISNUMBER(SEARCH(SUBSTITUTE('Référentiel films'!$A$41,"’","'"),SUBSTITUTE(G6,"’","'"))),'Référentiel films'!$B$41,""))) -> film-1972-le-marchand-des-quatre-saisons; film-1974-tous-les-autres-s-appellent-ali; film-1974-martha | I6: Dans les mélodrames de RWF , les personnages tentent en vain de s'affranchir des positions aliénantes produites par la famille, le couple, au sein du système capitaliste et de la classe bourgeoise. Une analogie s'établit alors entre famille et Allemagne. Le mélodrame fassbindérien met en scène des crises identitaires du sujet, comme crises de la perception (du regard), qui se traduisent par une mise en crise de l'image (image de soi et image du film). Les films font dialoguer subjectivité et affects avec mécanismes sociaux, évitant ainsi toute lecture simpliste et figées de type psychologique ou idéologique. Le mélodrame, en interpénétrant le privé et le public, l'individuel et le collectif, joue d'un trouble qui participe à son caractère critique et progressiste : il est potentiellement facteur de changement pour un spectateur constamment soumis à la réflexion.
A7: 1975-1976 | C7: Comment le rapport dominant/dominé structure-t-il toute relation, affective ou sociale ? | D7: Tensions sociales et crises du logement (Westend). Débats sur la visibilité des minorités. Lois limitant les libertés civiles. | E7: Développement du "film amphibie" (cinéma/TV). Le cinéma devient un outil de critique sociale directe. | F7: Scandale théâtral autour de la pièce L'Ordure, la ville et la mort (accusations d'antisémitisme). Liaison avec Armin Meier. | G7: Maman Küsters s'en va au ciel (1975). Le Droit du plus fort (1975) : | H7: =IF(G7="","",_xlfn.TEXTJOIN("; ",TRUE(),IF(ISNUMBER(SEARCH(SUBSTITUTE('Référentiel films'!$A$2,"’","'"),SUBSTITUTE(G7,"’","'"))),'Référentiel films'!$B$2,""),IF(ISNUMBER(SEARCH(SUBSTITUTE('Référentiel films'!$A$3,"’","'"),SUBSTITUTE(G7,"’","'"))),'Référentiel films'!$B$3,""),IF(ISNUMBER(SEARCH(SUBSTITUTE('Référentiel films'!$A$4,"’","'"),SUBSTITUTE(G7,"’","'"))),'Référentiel films'!$B$4,""),IF(ISNUMBER(SEARCH(SUBSTITUTE('Référentiel films'!$A$5,"’","'"),SUBSTITUTE(G7,"’","'"))),'Référentiel films'!$B$5,""),IF(ISNUMBER(SEARCH(SUBSTITUTE('Référentiel films'!$A$6,"’","'"),SUBSTITUTE(G7,"’","'"))),'Référentiel films'!$B$6,""),IF(ISNUMBER(SEARCH(SUBSTITUTE('Référentiel films'!$A$7,"’","'"),SUBSTITUTE(G7,"’","'"))),'Référentiel films'!$B$7,""),IF(ISNUMBER(SEARCH(SUBSTITUTE('Référentiel films'!$A$8,"’","'"),SUBSTITUTE(G7,"’","'"))),'Référentiel films'!$B$8,""),IF(ISNUMBER(SEARCH(SUBSTITUTE('Référentiel films'!$A$9,"’","'"),SUBSTITUTE(G7,"’","'"))),'Référentiel films'!$B$9,""),IF(ISNUMBER(SEARCH(SUBSTITUTE('Référentiel films'!$A$10,"’","'"),SUBSTITUTE(G7,"’","'"))),'Référentiel films'!$B$10,""),IF(ISNUMBER(SEARCH(SUBSTITUTE('Référentiel films'!$A$11,"’","'"),SUBSTITUTE(G7,"’","'"))),'Référentiel films'!$B$11,""),IF(ISNUMBER(SEARCH(SUBSTITUTE('Référentiel films'!$A$12,"’","'"),SUBSTITUTE(G7,"’","'"))),'Référentiel films'!$B$12,""),IF(ISNUMBER(SEARCH(SUBSTITUTE('Référentiel films'!$A$13,"’","'"),SUBSTITUTE(G7,"’","'"))),'Référentiel films'!$B$13,""),IF(ISNUMBER(SEARCH(SUBSTITUTE('Référentiel films'!$A$14,"’","'"),SUBSTITUTE(G7,"’","'"))),'Référentiel films'!$B$14,""),IF(ISNUMBER(SEARCH(SUBSTITUTE('Référentiel films'!$A$15,"’","'"),SUBSTITUTE(G7,"’","'"))),'Référentiel films'!$B$15,""),IF(ISNUMBER(SEARCH(SUBSTITUTE('Référentiel films'!$A$16,"’","'"),SUBSTITUTE(G7,"’","'"))),'Référentiel films'!$B$16,""),IF(ISNUMBER(SEARCH(SUBSTITUTE('Référentiel films'!$A$17,"’","'"),SUBSTITUTE(G7,"’","'"))),'Référentiel films'!$B$17,""),IF(ISNUMBER(SEARCH(SUBSTITUTE('Référentiel films'!$A$18,"’","'"),SUBSTITUTE(G7,"’","'"))),'Référentiel films'!$B$18,""),IF(ISNUMBER(SEARCH(SUBSTITUTE('Référentiel films'!$A$19,"’","'"),SUBSTITUTE(G7,"’","'"))),'Référentiel films'!$B$19,""),IF(ISNUMBER(SEARCH(SUBSTITUTE('Référentiel films'!$A$20,"’","'"),SUBSTITUTE(G7,"’","'"))),'Référentiel films'!$B$20,""),IF(ISNUMBER(SEARCH(SUBSTITUTE('Référentiel films'!$A$21,"’","'"),SUBSTITUTE(G7,"’","'"))),'Référentiel films'!$B$21,""),IF(ISNUMBER(SEARCH(SUBSTITUTE('Référentiel films'!$A$22,"’","'"),SUBSTITUTE(G7,"’","'"))),'Référentiel films'!$B$22,""),IF(ISNUMBER(SEARCH(SUBSTITUTE('Référentiel films'!$A$23,"’","'"),SUBSTITUTE(G7,"’","'"))),'Référentiel films'!$B$23,""),IF(ISNUMBER(SEARCH(SUBSTITUTE('Référentiel films'!$A$24,"’","'"),SUBSTITUTE(G7,"’","'"))),'Référentiel films'!$B$24,""),IF(ISNUMBER(SEARCH(SUBSTITUTE('Référentiel films'!$A$25,"’","'"),SUBSTITUTE(G7,"’","'"))),'Référentiel films'!$B$25,""),IF(ISNUMBER(SEARCH(SUBSTITUTE('Référentiel films'!$A$26,"’","'"),SUBSTITUTE(G7,"’","'"))),'Référentiel films'!$B$26,""),IF(ISNUMBER(SEARCH(SUBSTITUTE('Référentiel films'!$A$27,"’","'"),SUBSTITUTE(G7,"’","'"))),'Référentiel films'!$B$27,""),IF(ISNUMBER(SEARCH(SUBSTITUTE('Référentiel films'!$A$28,"’","'"),SUBSTITUTE(G7,"’","'"))),'Référentiel films'!$B$28,""),IF(ISNUMBER(SEARCH(SUBSTITUTE('Référentiel films'!$A$29,"’","'"),SUBSTITUTE(G7,"’","'"))),'Référentiel films'!$B$29,""),IF(ISNUMBER(SEARCH(SUBSTITUTE('Référentiel films'!$A$30,"’","'"),SUBSTITUTE(G7,"’","'"))),'Référentiel films'!$B$30,""),IF(ISNUMBER(SEARCH(SUBSTITUTE('Référentiel films'!$A$31,"’","'"),SUBSTITUTE(G7,"’","'"))),'Référentiel films'!$B$31,""),IF(ISNUMBER(SEARCH(SUBSTITUTE('Référentiel films'!$A$32,"’","'"),SUBSTITUTE(G7,"’","'"))),'Référentiel films'!$B$32,""),IF(ISNUMBER(SEARCH(SUBSTITUTE('Référentiel films'!$A$33,"’","'"),SUBSTITUTE(G7,"’","'"))),'Référentiel films'!$B$33,""),IF(ISNUMBER(SEARCH(SUBSTITUTE('Référentiel films'!$A$34,"’","'"),SUBSTITUTE(G7,"’","'"))),'Référentiel films'!$B$34,""),IF(ISNUMBER(SEARCH(SUBSTITUTE('Référentiel films'!$A$35,"’","'"),SUBSTITUTE(G7,"’","'"))),'Référentiel films'!$B$35,""),IF(ISNUMBER(SEARCH(SUBSTITUTE('Référentiel films'!$A$36,"’","'"),SUBSTITUTE(G7,"’","'"))),'Référentiel films'!$B$36,""),IF(ISNUMBER(SEARCH(SUBSTITUTE('Référentiel films'!$A$37,"’","'"),SUBSTITUTE(G7,"’","'"))),'Référentiel films'!$B$37,""),IF(ISNUMBER(SEARCH(SUBSTITUTE('Référentiel films'!$A$38,"’","'"),SUBSTITUTE(G7,"’","'"))),'Référentiel films'!$B$38,""),IF(ISNUMBER(SEARCH(SUBSTITUTE('Référentiel films'!$A$39,"’","'"),SUBSTITUTE(G7,"’","'"))),'Référentiel films'!$B$39,""),IF(ISNUMBER(SEARCH(SUBSTITUTE('Référentiel films'!$A$40,"’","'"),SUBSTITUTE(G7,"’","'"))),'Référentiel films'!$B$40,""),IF(ISNUMBER(SEARCH(SUBSTITUTE('Référentiel films'!$A$41,"’","'"),SUBSTITUTE(G7,"’","'"))),'Référentiel films'!$B$41,""))) -> film-1975-le-droit-du-plus-fort; film-1975-maman-kusters-s-en-va-au-ciel | I7: Fassbinder y joue un rôle principal, assumant une visibilité politique de son homosexualité.
A8: 1977-1979 | B8: Le retour de l'histoire | C8: Jusqu'à quel point les femmes de la trilogie RFA sont-elles une allégorie de la nation allemande ? Quelle distance RWF prend-il avec la critique historique de son pays ? | D8: Automne Allemand (1977) : enlèvement de Schleyer, détournement du Landshut, morts à Stammheim. | E8: Le cinéma allemand s'empare de son histoire passée et récente et réfléchit aux problèmes de représentation qu'elle pose. Film collectif L'Allemagne en automne (1978). La diffusion de la série Holocaust de Marvin J. Chomsky (1979) à la télévision allemande suscite des débats importants, auxquels participent des cinéastes comme Syberberg ou Edgard Reitz. Le mouvement du Nouveau Cinéma allemand atteint son apogée thématique et politique. | F8: Suicide d'Armin Meier (31 mai 1978). Début de la collaboration avec Juliane Lorenz. Fassbinder se filme en crise, exposant son angoisse face à l'État. | G8: L'Année des treize lunes (1978) : œuvre radicale sur le désespoir. Le Mariage de Maria Braun (1979) : triomphe international, allégorie de la reconstruction. | H8: =IF(G8="","",_xlfn.TEXTJOIN("; ",TRUE(),IF(ISNUMBER(SEARCH(SUBSTITUTE('Référentiel films'!$A$2,"’","'"),SUBSTITUTE(G8,"’","'"))),'Référentiel films'!$B$2,""),IF(ISNUMBER(SEARCH(SUBSTITUTE('Référentiel films'!$A$3,"’","'"),SUBSTITUTE(G8,"’","'"))),'Référentiel films'!$B$3,""),IF(ISNUMBER(SEARCH(SUBSTITUTE('Référentiel films'!$A$4,"’","'"),SUBSTITUTE(G8,"’","'"))),'Référentiel films'!$B$4,""),IF(ISNUMBER(SEARCH(SUBSTITUTE('Référentiel films'!$A$5,"’","'"),SUBSTITUTE(G8,"’","'"))),'Référentiel films'!$B$5,""),IF(ISNUMBER(SEARCH(SUBSTITUTE('Référentiel films'!$A$6,"’","'"),SUBSTITUTE(G8,"’","'"))),'Référentiel films'!$B$6,""),IF(ISNUMBER(SEARCH(SUBSTITUTE('Référentiel films'!$A$7,"’","'"),SUBSTITUTE(G8,"’","'"))),'Référentiel films'!$B$7,""),IF(ISNUMBER(SEARCH(SUBSTITUTE('Référentiel films'!$A$8,"’","'"),SUBSTITUTE(G8,"’","'"))),'Référentiel films'!$B$8,""),IF(ISNUMBER(SEARCH(SUBSTITUTE('Référentiel films'!$A$9,"’","'"),SUBSTITUTE(G8,"’","'"))),'Référentiel films'!$B$9,""),IF(ISNUMBER(SEARCH(SUBSTITUTE('Référentiel films'!$A$10,"’","'"),SUBSTITUTE(G8,"’","'"))),'Référentiel films'!$B$10,""),IF(ISNUMBER(SEARCH(SUBSTITUTE('Référentiel films'!$A$11,"’","'"),SUBSTITUTE(G8,"’","'"))),'Référentiel films'!$B$11,""),IF(ISNUMBER(SEARCH(SUBSTITUTE('Référentiel films'!$A$12,"’","'"),SUBSTITUTE(G8,"’","'"))),'Référentiel films'!$B$12,""),IF(ISNUMBER(SEARCH(SUBSTITUTE('Référentiel films'!$A$13,"’","'"),SUBSTITUTE(G8,"’","'"))),'Référentiel films'!$B$13,""),IF(ISNUMBER(SEARCH(SUBSTITUTE('Référentiel films'!$A$14,"’","'"),SUBSTITUTE(G8,"’","'"))),'Référentiel films'!$B$14,""),IF(ISNUMBER(SEARCH(SUBSTITUTE('Référentiel films'!$A$15,"’","'"),SUBSTITUTE(G8,"’","'"))),'Référentiel films'!$B$15,""),IF(ISNUMBER(SEARCH(SUBSTITUTE('Référentiel films'!$A$16,"’","'"),SUBSTITUTE(G8,"’","'"))),'Référentiel films'!$B$16,""),IF(ISNUMBER(SEARCH(SUBSTITUTE('Référentiel films'!$A$17,"’","'"),SUBSTITUTE(G8,"’","'"))),'Référentiel films'!$B$17,""),IF(ISNUMBER(SEARCH(SUBSTITUTE('Référentiel films'!$A$18,"’","'"),SUBSTITUTE(G8,"’","'"))),'Référentiel films'!$B$18,""),IF(ISNUMBER(SEARCH(SUBSTITUTE('Référentiel films'!$A$19,"’","'"),SUBSTITUTE(G8,"’","'"))),'Référentiel films'!$B$19,""),IF(ISNUMBER(SEARCH(SUBSTITUTE('Référentiel films'!$A$20,"’","'"),SUBSTITUTE(G8,"’","'"))),'Référentiel films'!$B$20,""),IF(ISNUMBER(SEARCH(SUBSTITUTE('Référentiel films'!$A$21,"’","'"),SUBSTITUTE(G8,"’","'"))),'Référentiel films'!$B$21,""),IF(ISNUMBER(SEARCH(SUBSTITUTE('Référentiel films'!$A$22,"’","'"),SUBSTITUTE(G8,"’","'"))),'Référentiel films'!$B$22,""),IF(ISNUMBER(SEARCH(SUBSTITUTE('Référentiel films'!$A$23,"’","'"),SUBSTITUTE(G8,"’","'"))),'Référentiel films'!$B$23,""),IF(ISNUMBER(SEARCH(SUBSTITUTE('Référentiel films'!$A$24,"’","'"),SUBSTITUTE(G8,"’","'"))),'Référentiel films'!$B$24,""),IF(ISNUMBER(SEARCH(SUBSTITUTE('Référentiel films'!$A$25,"’","'"),SUBSTITUTE(G8,"’","'"))),'Référentiel films'!$B$25,""),IF(ISNUMBER(SEARCH(SUBSTITUTE('Référentiel films'!$A$26,"’","'"),SUBSTITUTE(G8,"’","'"))),'Référentiel films'!$B$26,""),IF(ISNUMBER(SEARCH(SUBSTITUTE('Référentiel films'!$A$27,"’","'"),SUBSTITUTE(G8,"’","'"))),'Référentiel films'!$B$27,""),IF(ISNUMBER(SEARCH(SUBSTITUTE('Référentiel films'!$A$28,"’","'"),SUBSTITUTE(G8,"’","'"))),'Référentiel films'!$B$28,""),IF(ISNUMBER(SEARCH(SUBSTITUTE('Référentiel films'!$A$29,"’","'"),SUBSTITUTE(G8,"’","'"))),'Référentiel films'!$B$29,""),IF(ISNUMBER(SEARCH(SUBSTITUTE('Référentiel films'!$A$30,"’","'"),SUBSTITUTE(G8,"’","'"))),'Référentiel films'!$B$30,""),IF(ISNUMBER(SEARCH(SUBSTITUTE('Référentiel films'!$A$31,"’","'"),SUBSTITUTE(G8,"’","'"))),'Référentiel films'!$B$31,""),IF(ISNUMBER(SEARCH(SUBSTITUTE('Référentiel films'!$A$32,"’","'"),SUBSTITUTE(G8,"’","'"))),'Référentiel films'!$B$32,""),IF(ISNUMBER(SEARCH(SUBSTITUTE('Référentiel films'!$A$33,"’","'"),SUBSTITUTE(G8,"’","'"))),'Référentiel films'!$B$33,""),IF(ISNUMBER(SEARCH(SUBSTITUTE('Référentiel films'!$A$34,"’","'"),SUBSTITUTE(G8,"’","'"))),'Référentiel films'!$B$34,""),IF(ISNUMBER(SEARCH(SUBSTITUTE('Référentiel films'!$A$35,"’","'"),SUBSTITUTE(G8,"’","'"))),'Référentiel films'!$B$35,""),IF(ISNUMBER(SEARCH(SUBSTITUTE('Référentiel films'!$A$36,"’","'"),SUBSTITUTE(G8,"’","'"))),'Référentiel films'!$B$36,""),IF(ISNUMBER(SEARCH(SUBSTITUTE('Référentiel films'!$A$37,"’","'"),SUBSTITUTE(G8,"’","'"))),'Référentiel films'!$B$37,""),IF(ISNUMBER(SEARCH(SUBSTITUTE('Référentiel films'!$A$38,"’","'"),SUBSTITUTE(G8,"’","'"))),'Référentiel films'!$B$38,""),IF(ISNUMBER(SEARCH(SUBSTITUTE('Référentiel films'!$A$39,"’","'"),SUBSTITUTE(G8,"’","'"))),'Référentiel films'!$B$39,""),IF(ISNUMBER(SEARCH(SUBSTITUTE('Référentiel films'!$A$40,"’","'"),SUBSTITUTE(G8,"’","'"))),'Référentiel films'!$B$40,""),IF(ISNUMBER(SEARCH(SUBSTITUTE('Référentiel films'!$A$41,"’","'"),SUBSTITUTE(G8,"’","'"))),'Référentiel films'!$B$41,""))) -> film-1978-l-annee-des-treize-lunes; film-1978-le-mariage-de-maria-braun | K8: le cinéaste Edgar Reitz affirme la nécessité " de films, de livres, d'images qui nous fassent reprendre connaissance et rétablissent nos réflexes", Medium, 5/1979, p.21 | N8: mélodrame
A9: 1980-1981 | B9: La fin d'un ère | C9: Quelles ambitions pour la série télévisuelle ? | D9: Fondation des Verts (1980). Manifestations écologistes. Fin de l'ère sociale-libérale. | F9: Travaille frénétiquement. Réalise son projet de vie : l'adaptation de Döblin. Épuisement physique dû aux excès. | G9: Monumental Berlin Alexanderplatz (1980, 15h). Suite de la Trilogie de la RFA : Lola, une femme allemande (1981) et Lili Marleen (1981). | H9: =IF(G9="","",_xlfn.TEXTJOIN("; ",TRUE(),IF(ISNUMBER(SEARCH(SUBSTITUTE('Référentiel films'!$A$2,"’","'"),SUBSTITUTE(G9,"’","'"))),'Référentiel films'!$B$2,""),IF(ISNUMBER(SEARCH(SUBSTITUTE('Référentiel films'!$A$3,"’","'"),SUBSTITUTE(G9,"’","'"))),'Référentiel films'!$B$3,""),IF(ISNUMBER(SEARCH(SUBSTITUTE('Référentiel films'!$A$4,"’","'"),SUBSTITUTE(G9,"’","'"))),'Référentiel films'!$B$4,""),IF(ISNUMBER(SEARCH(SUBSTITUTE('Référentiel films'!$A$5,"’","'"),SUBSTITUTE(G9,"’","'"))),'Référentiel films'!$B$5,""),IF(ISNUMBER(SEARCH(SUBSTITUTE('Référentiel films'!$A$6,"’","'"),SUBSTITUTE(G9,"’","'"))),'Référentiel films'!$B$6,""),IF(ISNUMBER(SEARCH(SUBSTITUTE('Référentiel films'!$A$7,"’","'"),SUBSTITUTE(G9,"’","'"))),'Référentiel films'!$B$7,""),IF(ISNUMBER(SEARCH(SUBSTITUTE('Référentiel films'!$A$8,"’","'"),SUBSTITUTE(G9,"’","'"))),'Référentiel films'!$B$8,""),IF(ISNUMBER(SEARCH(SUBSTITUTE('Référentiel films'!$A$9,"’","'"),SUBSTITUTE(G9,"’","'"))),'Référentiel films'!$B$9,""),IF(ISNUMBER(SEARCH(SUBSTITUTE('Référentiel films'!$A$10,"’","'"),SUBSTITUTE(G9,"’","'"))),'Référentiel films'!$B$10,""),IF(ISNUMBER(SEARCH(SUBSTITUTE('Référentiel films'!$A$11,"’","'"),SUBSTITUTE(G9,"’","'"))),'Référentiel films'!$B$11,""),IF(ISNUMBER(SEARCH(SUBSTITUTE('Référentiel films'!$A$12,"’","'"),SUBSTITUTE(G9,"’","'"))),'Référentiel films'!$B$12,""),IF(ISNUMBER(SEARCH(SUBSTITUTE('Référentiel films'!$A$13,"’","'"),SUBSTITUTE(G9,"’","'"))),'Référentiel films'!$B$13,""),IF(ISNUMBER(SEARCH(SUBSTITUTE('Référentiel films'!$A$14,"’","'"),SUBSTITUTE(G9,"’","'"))),'Référentiel films'!$B$14,""),IF(ISNUMBER(SEARCH(SUBSTITUTE('Référentiel films'!$A$15,"’","'"),SUBSTITUTE(G9,"’","'"))),'Référentiel films'!$B$15,""),IF(ISNUMBER(SEARCH(SUBSTITUTE('Référentiel films'!$A$16,"’","'"),SUBSTITUTE(G9,"’","'"))),'Référentiel films'!$B$16,""),IF(ISNUMBER(SEARCH(SUBSTITUTE('Référentiel films'!$A$17,"’","'"),SUBSTITUTE(G9,"’","'"))),'Référentiel films'!$B$17,""),IF(ISNUMBER(SEARCH(SUBSTITUTE('Référentiel films'!$A$18,"’","'"),SUBSTITUTE(G9,"’","'"))),'Référentiel films'!$B$18,""),IF(ISNUMBER(SEARCH(SUBSTITUTE('Référentiel films'!$A$19,"’","'"),SUBSTITUTE(G9,"’","'"))),'Référentiel films'!$B$19,""),IF(ISNUMBER(SEARCH(SUBSTITUTE('Référentiel films'!$A$20,"’","'"),SUBSTITUTE(G9,"’","'"))),'Référentiel films'!$B$20,""),IF(ISNUMBER(SEARCH(SUBSTITUTE('Référentiel films'!$A$21,"’","'"),SUBSTITUTE(G9,"’","'"))),'Référentiel films'!$B$21,""),IF(ISNUMBER(SEARCH(SUBSTITUTE('Référentiel films'!$A$22,"’","'"),SUBSTITUTE(G9,"’","'"))),'Référentiel films'!$B$22,""),IF(ISNUMBER(SEARCH(SUBSTITUTE('Référentiel films'!$A$23,"’","'"),SUBSTITUTE(G9,"’","'"))),'Référentiel films'!$B$23,""),IF(ISNUMBER(SEARCH(SUBSTITUTE('Référentiel films'!$A$24,"’","'"),SUBSTITUTE(G9,"’","'"))),'Référentiel films'!$B$24,""),IF(ISNUMBER(SEARCH(SUBSTITUTE('Référentiel films'!$A$25,"’","'"),SUBSTITUTE(G9,"’","'"))),'Référentiel films'!$B$25,""),IF(ISNUMBER(SEARCH(SUBSTITUTE('Référentiel films'!$A$26,"’","'"),SUBSTITUTE(G9,"’","'"))),'Référentiel films'!$B$26,""),IF(ISNUMBER(SEARCH(SUBSTITUTE('Référentiel films'!$A$27,"’","'"),SUBSTITUTE(G9,"’","'"))),'Référentiel films'!$B$27,""),IF(ISNUMBER(SEARCH(SUBSTITUTE('Référentiel films'!$A$28,"’","'"),SUBSTITUTE(G9,"’","'"))),'Référentiel films'!$B$28,""),IF(ISNUMBER(SEARCH(SUBSTITUTE('Référentiel films'!$A$29,"’","'"),SUBSTITUTE(G9,"’","'"))),'Référentiel films'!$B$29,""),IF(ISNUMBER(SEARCH(SUBSTITUTE('Référentiel films'!$A$30,"’","'"),SUBSTITUTE(G9,"’","'"))),'Référentiel films'!$B$30,""),IF(ISNUMBER(SEARCH(SUBSTITUTE('Référentiel films'!$A$31,"’","'"),SUBSTITUTE(G9,"’","'"))),'Référentiel films'!$B$31,""),IF(ISNUMBER(SEARCH(SUBSTITUTE('Référentiel films'!$A$32,"’","'"),SUBSTITUTE(G9,"’","'"))),'Référentiel films'!$B$32,""),IF(ISNUMBER(SEARCH(SUBSTITUTE('Référentiel films'!$A$33,"’","'"),SUBSTITUTE(G9,"’","'"))),'Référentiel films'!$B$33,""),IF(ISNUMBER(SEARCH(SUBSTITUTE('Référentiel films'!$A$34,"’","'"),SUBSTITUTE(G9,"’","'"))),'Référentiel films'!$B$34,""),IF(ISNUMBER(SEARCH(SUBSTITUTE('Référentiel films'!$A$35,"’","'"),SUBSTITUTE(G9,"’","'"))),'Référentiel films'!$B$35,""),IF(ISNUMBER(SEARCH(SUBSTITUTE('Référentiel films'!$A$36,"’","'"),SUBSTITUTE(G9,"’","'"))),'Référentiel films'!$B$36,""),IF(ISNUMBER(SEARCH(SUBSTITUTE('Référentiel films'!$A$37,"’","'"),SUBSTITUTE(G9,"’","'"))),'Référentiel films'!$B$37,""),IF(ISNUMBER(SEARCH(SUBSTITUTE('Référentiel films'!$A$38,"’","'"),SUBSTITUTE(G9,"’","'"))),'Référentiel films'!$B$38,""),IF(ISNUMBER(SEARCH(SUBSTITUTE('Référentiel films'!$A$39,"’","'"),SUBSTITUTE(G9,"’","'"))),'Référentiel films'!$B$39,""),IF(ISNUMBER(SEARCH(SUBSTITUTE('Référentiel films'!$A$40,"’","'"),SUBSTITUTE(G9,"’","'"))),'Référentiel films'!$B$40,""),IF(ISNUMBER(SEARCH(SUBSTITUTE('Référentiel films'!$A$41,"’","'"),SUBSTITUTE(G9,"’","'"))),'Référentiel films'!$B$41,""))) -> film-1980-berlin-alexanderplatz; film-1981-lili-marleen; film-1981-lola-une-femme-allemande
A10: 1982 | B10: La mort du Maître | C10: RWF, figure du collectif politique des années 60 et 70 ou d'héritier de la figure du génie romantique et du poète maudit ? Auteur ou cinéaste populaire ? | D10: Victoire d'Helmut Kohl (CDU) en octobre. Fin d'une époque artistique et politique radicale. | E10: Mort de Fassbinder marquant symboliquement la fin du Nouveau Cinéma Allemand. | F10: Décès de Fassbinder le 10 juin à Munich, à l'âge de 37 ans (épuisement et overdose). | G10: Le Secret de Veronika Voss (Ours d'Or à Berlin). Querelle (œuvre posthume). Fassbinder laisse un héritage de plus de 40 films. | H10: =IF(G10="","",_xlfn.TEXTJOIN("; ",TRUE(),IF(ISNUMBER(SEARCH(SUBSTITUTE('Référentiel films'!$A$2,"’","'"),SUBSTITUTE(G10,"’","'"))),'Référentiel films'!$B$2,""),IF(ISNUMBER(SEARCH(SUBSTITUTE('Référentiel films'!$A$3,"’","'"),SUBSTITUTE(G10,"’","'"))),'Référentiel films'!$B$3,""),IF(ISNUMBER(SEARCH(SUBSTITUTE('Référentiel films'!$A$4,"’","'"),SUBSTITUTE(G10,"’","'"))),'Référentiel films'!$B$4,""),IF(ISNUMBER(SEARCH(SUBSTITUTE('Référentiel films'!$A$5,"’","'"),SUBSTITUTE(G10,"’","'"))),'Référentiel films'!$B$5,""),IF(ISNUMBER(SEARCH(SUBSTITUTE('Référentiel films'!$A$6,"’","'"),SUBSTITUTE(G10,"’","'"))),'Référentiel films'!$B$6,""),IF(ISNUMBER(SEARCH(SUBSTITUTE('Référentiel films'!$A$7,"’","'"),SUBSTITUTE(G10,"’","'"))),'Référentiel films'!$B$7,""),IF(ISNUMBER(SEARCH(SUBSTITUTE('Référentiel films'!$A$8,"’","'"),SUBSTITUTE(G10,"’","'"))),'Référentiel films'!$B$8,""),IF(ISNUMBER(SEARCH(SUBSTITUTE('Référentiel films'!$A$9,"’","'"),SUBSTITUTE(G10,"’","'"))),'Référentiel films'!$B$9,""),IF(ISNUMBER(SEARCH(SUBSTITUTE('Référentiel films'!$A$10,"’","'"),SUBSTITUTE(G10,"’","'"))),'Référentiel films'!$B$10,""),IF(ISNUMBER(SEARCH(SUBSTITUTE('Référentiel films'!$A$11,"’","'"),SUBSTITUTE(G10,"’","'"))),'Référentiel films'!$B$11,""),IF(ISNUMBER(SEARCH(SUBSTITUTE('Référentiel films'!$A$12,"’","'"),SUBSTITUTE(G10,"’","'"))),'Référentiel films'!$B$12,""),IF(ISNUMBER(SEARCH(SUBSTITUTE('Référentiel films'!$A$13,"’","'"),SUBSTITUTE(G10,"’","'"))),'Référentiel films'!$B$13,""),IF(ISNUMBER(SEARCH(SUBSTITUTE('Référentiel films'!$A$14,"’","'"),SUBSTITUTE(G10,"’","'"))),'Référentiel films'!$B$14,""),IF(ISNUMBER(SEARCH(SUBSTITUTE('Référentiel films'!$A$15,"’","'"),SUBSTITUTE(G10,"’","'"))),'Référentiel films'!$B$15,""),IF(ISNUMBER(SEARCH(SUBSTITUTE('Référentiel films'!$A$16,"’","'"),SUBSTITUTE(G10,"’","'"))),'Référentiel films'!$B$16,""),IF(ISNUMBER(SEARCH(SUBSTITUTE('Référentiel films'!$A$17,"’","'"),SUBSTITUTE(G10,"’","'"))),'Référentiel films'!$B$17,""),IF(ISNUMBER(SEARCH(SUBSTITUTE('Référentiel films'!$A$18,"’","'"),SUBSTITUTE(G10,"’","'"))),'Référentiel films'!$B$18,""),IF(ISNUMBER(SEARCH(SUBSTITUTE('Référentiel films'!$A$19,"’","'"),SUBSTITUTE(G10,"’","'"))),'Référentiel films'!$B$19,""),IF(ISNUMBER(SEARCH(SUBSTITUTE('Référentiel films'!$A$20,"’","'"),SUBSTITUTE(G10,"’","'"))),'Référentiel films'!$B$20,""),IF(ISNUMBER(SEARCH(SUBSTITUTE('Référentiel films'!$A$21,"’","'"),SUBSTITUTE(G10,"’","'"))),'Référentiel films'!$B$21,""),IF(ISNUMBER(SEARCH(SUBSTITUTE('Référentiel films'!$A$22,"’","'"),SUBSTITUTE(G10,"’","'"))),'Référentiel films'!$B$22,""),IF(ISNUMBER(SEARCH(SUBSTITUTE('Référentiel films'!$A$23,"’","'"),SUBSTITUTE(G10,"’","'"))),'Référentiel films'!$B$23,""),IF(ISNUMBER(SEARCH(SUBSTITUTE('Référentiel films'!$A$24,"’","'"),SUBSTITUTE(G10,"’","'"))),'Référentiel films'!$B$24,""),IF(ISNUMBER(SEARCH(SUBSTITUTE('Référentiel films'!$A$25,"’","'"),SUBSTITUTE(G10,"’","'"))),'Référentiel films'!$B$25,""),IF(ISNUMBER(SEARCH(SUBSTITUTE('Référentiel films'!$A$26,"’","'"),SUBSTITUTE(G10,"’","'"))),'Référentiel films'!$B$26,""),IF(ISNUMBER(SEARCH(SUBSTITUTE('Référentiel films'!$A$27,"’","'"),SUBSTITUTE(G10,"’","'"))),'Référentiel films'!$B$27,""),IF(ISNUMBER(SEARCH(SUBSTITUTE('Référentiel films'!$A$28,"’","'"),SUBSTITUTE(G10,"’","'"))),'Référentiel films'!$B$28,""),IF(ISNUMBER(SEARCH(SUBSTITUTE('Référentiel films'!$A$29,"’","'"),SUBSTITUTE(G10,"’","'"))),'Référentiel films'!$B$29,""),IF(ISNUMBER(SEARCH(SUBSTITUTE('Référentiel films'!$A$30,"’","'"),SUBSTITUTE(G10,"’","'"))),'Référentiel films'!$B$30,""),IF(ISNUMBER(SEARCH(SUBSTITUTE('Référentiel films'!$A$31,"’","'"),SUBSTITUTE(G10,"’","'"))),'Référentiel films'!$B$31,""),IF(ISNUMBER(SEARCH(SUBSTITUTE('Référentiel films'!$A$32,"’","'"),SUBSTITUTE(G10,"’","'"))),'Référentiel films'!$B$32,""),IF(ISNUMBER(SEARCH(SUBSTITUTE('Référentiel films'!$A$33,"’","'"),SUBSTITUTE(G10,"’","'"))),'Référentiel films'!$B$33,""),IF(ISNUMBER(SEARCH(SUBSTITUTE('Référentiel films'!$A$34,"’","'"),SUBSTITUTE(G10,"’","'"))),'Référentiel films'!$B$34,""),IF(ISNUMBER(SEARCH(SUBSTITUTE('Référentiel films'!$A$35,"’","'"),SUBSTITUTE(G10,"’","'"))),'Référentiel films'!$B$35,""),IF(ISNUMBER(SEARCH(SUBSTITUTE('Référentiel films'!$A$36,"’","'"),SUBSTITUTE(G10,"’","'"))),'Référentiel films'!$B$36,""),IF(ISNUMBER(SEARCH(SUBSTITUTE('Référentiel films'!$A$37,"’","'"),SUBSTITUTE(G10,"’","'"))),'Référentiel films'!$B$37,""),IF(ISNUMBER(SEARCH(SUBSTITUTE('Référentiel films'!$A$38,"’","'"),SUBSTITUTE(G10,"’","'"))),'Référentiel films'!$B$38,""),IF(ISNUMBER(SEARCH(SUBSTITUTE('Référentiel films'!$A$39,"’","'"),SUBSTITUTE(G10,"’","'"))),'Référentiel films'!$B$39,""),IF(ISNUMBER(SEARCH(SUBSTITUTE('Référentiel films'!$A$40,"’","'"),SUBSTITUTE(G10,"’","'"))),'Référentiel films'!$B$40,""),IF(ISNUMBER(SEARCH(SUBSTITUTE('Référentiel films'!$A$41,"’","'"),SUBSTITUTE(G10,"’","'"))),'Référentiel films'!$B$41,""))) -> film-1981-le-secret-de-veronika-voss; film-1982-querelle

Sheet Années
A1: Année | B1: ID période | C1: Événement histoire et politique | D1: Contexte culturel | E1: Biographie de Fassbinder | F1: Œuvres | G1: Analyse et Réception critique | H1: Liens | I1: Extraits | J1: Description de l'extrait | K1: Consigne d'analyse | L1: Citation | M1: Image 1 | N1: Légende 1 | O1: Image 2 | P1: Légende 2 | Q1: Image 3 | R1: Légende 3 | S1: Notion | T1: Source | U1: IDs films — Œuvres
